Workbook
Name Accounts: #REF!
Name datab: #REF!
Name skrange: #REF!

Sheet FNR Telemark til rapport
B2: Analyse - Telemark og landet samlet
B3: Fra FNR
B6: Verdiskapning (bruttoprodukt)
B7: Gule celler - estimerte verdier etter fylkessammenslåing | K7: BDO Estimert
C8: 2012 | D8: 2013 | E8: 2014 | F8: 2015 | G8: 2016 | H8: 2017 | I8: 2018 | J8: 2019 | K8: 2020 | L8: 2021 | M8: 2022 | N8: 2023 | O8: 2024
B9: 08 Telemark (-2019)
B10: Totalt for næringer | C10: {=_xlfn.XLOOKUP($B$9&$B10,'FNR tidsserier'!$B$7:$B$182&'FNR tidsserier'!$C$7:$C$182,INDEX('FNR tidsserier'!$D$7:$R$182,,MATCH(C$8,'FNR tidsserier'!$D$7:$R$7,0)),"ikke funnet")} -> 53232 | D10: {=_xlfn.XLOOKUP($B$9&$B10,'FNR tidsserier'!$B$7:$B$182&'FNR tidsserier'!$C$7:$C$182,INDEX('FNR tidsserier'!$D$7:$R$182,,MATCH(D$8,'FNR tidsserier'!$D$7:$R$7,0)),"ikke funnet")} -> 55740 | E10: {=_xlfn.XLOOKUP($B$9&$B10,'FNR tidsserier'!$B$7:$B$182&'FNR tidsserier'!$C$7:$C$182,INDEX('FNR tidsserier'!$D$7:$R$182,,MATCH(E$8,'FNR tidsserier'!$D$7:$R$7,0)),"ikke funnet")} -> 57692 | F10: {=_xlfn.XLOOKUP($B$9&$B10,'FNR tidsserier'!$B$7:$B$182&'FNR tidsserier'!$C$7:$C$182,INDEX('FNR tidsserier'!$D$7:$R$182,,MATCH(F$8,'FNR tidsserier'!$D$7:$R$7,0)),"ikke funnet")} -> 62342 | G10: {=_xlfn.XLOOKUP($B$9&$B10,'FNR tidsserier'!$B$7:$B$182&'FNR tidsserier'!$C$7:$C$182,INDEX('FNR tidsserier'!$D$7:$R$182,,MATCH(G$8,'FNR tidsserier'!$D$7:$R$7,0)),"ikke funnet")} -> 62442 | H10: {=_xlfn.XLOOKUP($B$9&$B10,'FNR tidsserier'!$B$7:$B$182&'FNR tidsserier'!$C$7:$C$182,INDEX('FNR tidsserier'!$D$7:$R$182,,MATCH(H$8,'FNR tidsserier'!$D$7:$R$7,0)),"ikke funnet")} -> 65409 | I10: {=_xlfn.XLOOKUP($B$9&$B10,'FNR tidsserier'!$B$7:$B$182&'FNR tidsserier'!$C$7:$C$182,INDEX('FNR tidsserier'!$D$7:$R$182,,MATCH(I$8,'FNR tidsserier'!$D$7:$R$7,0)),"ikke funnet")} -> 70772 | J10: {=_xlfn.XLOOKUP($B$9&$B10,'FNR tidsserier'!$B$7:$B$182&'FNR tidsserier'!$C$7:$C$182,INDEX('FNR tidsserier'!$D$7:$R$182,,MATCH(J$8,'FNR tidsserier'!$D$7:$R$7,0)),"ikke funnet")} -> 72842 | ... M10: {=_xlfn.XLOOKUP($B$9&$B10,'FNR tidsserier'!$B$7:$B$182&'FNR tidsserier'!$C$7:$C$182,INDEX('FNR tidsserier'!$D$7:$R$182,,MATCH(M$8,'FNR tidsserier'!$D$7:$R$7,0)),"ikke funnet")} -> 89798.138 | N10: ='FNR Telemark estimert'!H33 -> 86489.868 | O10: ='FNR Telemark estimert'!I33 -> 87593.616
B12: Landet uten sokkelen
B13: Totalt for næringer | C13: {=_xlfn.XLOOKUP($B$12&$B13,'FNR tidsserier'!$B$7:$B$182&'FNR tidsserier'!$C$7:$C$182,INDEX('FNR tidsserier'!$D$7:$R$182,,MATCH(C$8,'FNR tidsserier'!$D$7:$R$7,0)),"ikke funnet")} -> 2027608 | D13: {=_xlfn.XLOOKUP($B$12&$B13,'FNR tidsserier'!$B$7:$B$182&'FNR tidsserier'!$C$7:$C$182,INDEX('FNR tidsserier'!$D$7:$R$182,,MATCH(D$8,'FNR tidsserier'!$D$7:$R$7,0)),"ikke funnet")} -> 2144146 | E13: {=_xlfn.XLOOKUP($B$12&$B13,'FNR tidsserier'!$B$7:$B$182&'FNR tidsserier'!$C$7:$C$182,INDEX('FNR tidsserier'!$D$7:$R$182,,MATCH(E$8,'FNR tidsserier'!$D$7:$R$7,0)),"ikke funnet")} -> 2249200 | F13: {=_xlfn.XLOOKUP($B$12&$B13,'FNR tidsserier'!$B$7:$B$182&'FNR tidsserier'!$C$7:$C$182,INDEX('FNR tidsserier'!$D$7:$R$182,,MATCH(F$8,'FNR tidsserier'!$D$7:$R$7,0)),"ikke funnet")} -> 2338475 | G13: {=_xlfn.XLOOKUP($B$12&$B13,'FNR tidsserier'!$B$7:$B$182&'FNR tidsserier'!$C$7:$C$182,INDEX('FNR tidsserier'!$D$7:$R$182,,MATCH(G$8,'FNR tidsserier'!$D$7:$R$7,0)),"ikke funnet")} -> 2396324 | H13: {=_xlfn.XLOOKUP($B$12&$B13,'FNR tidsserier'!$B$7:$B$182&'FNR tidsserier'!$C$7:$C$182,INDEX('FNR tidsserier'!$D$7:$R$182,,MATCH(H$8,'FNR tidsserier'!$D$7:$R$7,0)),"ikke funnet")} -> 2481464 | I13: {=_xlfn.XLOOKUP($B$12&$B13,'FNR tidsserier'!$B$7:$B$182&'FNR tidsserier'!$C$7:$C$182,INDEX('FNR tidsserier'!$D$7:$R$182,,MATCH(I$8,'FNR tidsserier'!$D$7:$R$7,0)),"ikke funnet")} -> 2593273 | J13: {=_xlfn.XLOOKUP($B$12&$B13,'FNR tidsserier'!$B$7:$B$182&'FNR tidsserier'!$C$7:$C$182,INDEX('FNR tidsserier'!$D$7:$R$182,,MATCH(J$8,'FNR tidsserier'!$D$7:$R$7,0)),"ikke funnet")} -> 2729146 | ... M13: {=_xlfn.XLOOKUP($B$12&$B13,'FNR tidsserier'!$B$7:$B$182&'FNR tidsserier'!$C$7:$C$182,INDEX('FNR tidsserier'!$D$7:$R$182,,MATCH(M$8,'FNR tidsserier'!$D$7:$R$7,0)),"ikke funnet")} -> 3341551 | N13: 3424887 | O13: 3573771
B15: Telemark - Normalisert
B16: =B10 -> Totalt for næringer | C16: =C10/$C10 -> 1 | D16: =D10/$C10 -> 1.0471145 | E16: =E10/$C10 -> 1.0837842 | F16: =F10/$C10 -> 1.1711377 | G16: =G10/$C10 -> 1.1730162 | H16: =H10/$C10 -> 1.2287534 | I16: =I10/$C10 -> 1.3295011 | J16: =J10/$C10 -> 1.3683874 | ... O16: =O10/$C10 -> 1.6455068
B18: Landet uten sokkelen - normalisert
B19: =B13 -> Totalt for næringer | C19: =C13/$C13 -> 1 | D19: =D13/$C13 -> 1.0574756 | E19: =E13/$C13 -> 1.1092874 | F19: =F13/$C13 -> 1.1533171 | G19: =G13/$C13 -> 1.1818478 | H19: =H13/$C13 -> 1.2238381 | I19: =I13/$C13 -> 1.2789814 | J19: =J13/$C13 -> 1.3459929 | ... O19: =O13/$C13 -> 1.7625552
B24: Sysselsetting
B25: Blå celler - estimerte verdier etter fylkessammenslåing | K25: BDO Estimert
C26: 2012 | D26: 2013 | E26: 2014 | F26: 2015 | G26: 2016 | H26: 2017 | I26: 2018 | J26: 2019 | K26: 2020 | L26: 2021 | M26: 2022 | N26: 2023 | O26: 2024
B27: 08 Telemark (-2019)
B28: Totalt for næringer | C28: {=_xlfn.XLOOKUP($B$27&$B28,'FNR tidsserier'!$B$7:$B$182&'FNR tidsserier'!$C$7:$C$182,INDEX('FNR tidsserier'!$S$7:$AG$182,,MATCH(C$26,'FNR tidsserier'!$S$7:$AG$7,0)),"ikke funnet")} -> 33992 | D28: {=_xlfn.XLOOKUP($B$27&$B28,'FNR tidsserier'!$B$7:$B$182&'FNR tidsserier'!$C$7:$C$182,INDEX('FNR tidsserier'!$S$7:$AG$182,,MATCH(D$26,'FNR tidsserier'!$S$7:$AG$7,0)),"ikke funnet")} -> 35318 | E28: {=_xlfn.XLOOKUP($B$27&$B28,'FNR tidsserier'!$B$7:$B$182&'FNR tidsserier'!$C$7:$C$182,INDEX('FNR tidsserier'!$S$7:$AG$182,,MATCH(E$26,'FNR tidsserier'!$S$7:$AG$7,0)),"ikke funnet")} -> 36666 | F28: {=_xlfn.XLOOKUP($B$27&$B28,'FNR tidsserier'!$B$7:$B$182&'FNR tidsserier'!$C$7:$C$182,INDEX('FNR tidsserier'!$S$7:$AG$182,,MATCH(F$26,'FNR tidsserier'!$S$7:$AG$7,0)),"ikke funnet")} -> 37331 | G28: {=_xlfn.XLOOKUP($B$27&$B28,'FNR tidsserier'!$B$7:$B$182&'FNR tidsserier'!$C$7:$C$182,INDEX('FNR tidsserier'!$S$7:$AG$182,,MATCH(G$26,'FNR tidsserier'!$S$7:$AG$7,0)),"ikke funnet")} -> 38737 | H28: {=_xlfn.XLOOKUP($B$27&$B28,'FNR tidsserier'!$B$7:$B$182&'FNR tidsserier'!$C$7:$C$182,INDEX('FNR tidsserier'!$S$7:$AG$182,,MATCH(H$26,'FNR tidsserier'!$S$7:$AG$7,0)),"ikke funnet")} -> 40119 | I28: {=_xlfn.XLOOKUP($B$27&$B28,'FNR tidsserier'!$B$7:$B$182&'FNR tidsserier'!$C$7:$C$182,INDEX('FNR tidsserier'!$S$7:$AG$182,,MATCH(I$26,'FNR tidsserier'!$S$7:$AG$7,0)),"ikke funnet")} -> 42242 | J28: {=_xlfn.XLOOKUP($B$27&$B28,'FNR tidsserier'!$B$7:$B$182&'FNR tidsserier'!$C$7:$C$182,INDEX('FNR tidsserier'!$S$7:$AG$182,,MATCH(J$26,'FNR tidsserier'!$S$7:$AG$7,0)),"ikke funnet")} -> 44616 | ... M28: {=_xlfn.XLOOKUP($B$27&$B28,'FNR tidsserier'!$B$7:$B$182&'FNR tidsserier'!$C$7:$C$182,INDEX('FNR tidsserier'!$S$7:$AG$182,,MATCH(M$26,'FNR tidsserier'!$S$7:$AG$7,0)),"ikke funnet")} -> 50433.366 | N28: =M28*(SUM(sys_næring_tfk[2023])/SUM(sys_næring_tfk[2022])) -> 50917.784 | O28: =N28*(SUM(sys_næring_tfk[2024])/SUM(sys_næring_tfk[2023])) -> 51269.555
B30: Landet uten sokkelen
B31: Totalt for næringer | C31: {=_xlfn.XLOOKUP($B$30&$B31,'FNR tidsserier'!$B$7:$B$182&'FNR tidsserier'!$C$7:$C$182,INDEX('FNR tidsserier'!$S$7:$AG$182,,MATCH(C$26,'FNR tidsserier'!$S$7:$AG$7,0)),"ikke funnet")} -> 1284398 | D31: {=_xlfn.XLOOKUP($B$30&$B31,'FNR tidsserier'!$B$7:$B$182&'FNR tidsserier'!$C$7:$C$182,INDEX('FNR tidsserier'!$S$7:$AG$182,,MATCH(D$26,'FNR tidsserier'!$S$7:$AG$7,0)),"ikke funnet")} -> 1357601 | E31: {=_xlfn.XLOOKUP($B$30&$B31,'FNR tidsserier'!$B$7:$B$182&'FNR tidsserier'!$C$7:$C$182,INDEX('FNR tidsserier'!$S$7:$AG$182,,MATCH(E$26,'FNR tidsserier'!$S$7:$AG$7,0)),"ikke funnet")} -> 1415222 | F31: {=_xlfn.XLOOKUP($B$30&$B31,'FNR tidsserier'!$B$7:$B$182&'FNR tidsserier'!$C$7:$C$182,INDEX('FNR tidsserier'!$S$7:$AG$182,,MATCH(F$26,'FNR tidsserier'!$S$7:$AG$7,0)),"ikke funnet")} -> 1476138 | G31: {=_xlfn.XLOOKUP($B$30&$B31,'FNR tidsserier'!$B$7:$B$182&'FNR tidsserier'!$C$7:$C$182,INDEX('FNR tidsserier'!$S$7:$AG$182,,MATCH(G$26,'FNR tidsserier'!$S$7:$AG$7,0)),"ikke funnet")} -> 1501058 | H31: {=_xlfn.XLOOKUP($B$30&$B31,'FNR tidsserier'!$B$7:$B$182&'FNR tidsserier'!$C$7:$C$182,INDEX('FNR tidsserier'!$S$7:$AG$182,,MATCH(H$26,'FNR tidsserier'!$S$7:$AG$7,0)),"ikke funnet")} -> 1550136 | I31: {=_xlfn.XLOOKUP($B$30&$B31,'FNR tidsserier'!$B$7:$B$182&'FNR tidsserier'!$C$7:$C$182,INDEX('FNR tidsserier'!$S$7:$AG$182,,MATCH(I$26,'FNR tidsserier'!$S$7:$AG$7,0)),"ikke funnet")} -> 1628407 | J31: {=_xlfn.XLOOKUP($B$30&$B31,'FNR tidsserier'!$B$7:$B$182&'FNR tidsserier'!$C$7:$C$182,INDEX('FNR tidsserier'!$S$7:$AG$182,,MATCH(J$26,'FNR tidsserier'!$S$7:$AG$7,0)),"ikke funnet")} -> 1721786 | ... M31: {=_xlfn.XLOOKUP($B$30&$B31,'FNR tidsserier'!$B$7:$B$182&'FNR tidsserier'!$C$7:$C$182,INDEX('FNR tidsserier'!$S$7:$AG$182,,MATCH(M$26,'FNR tidsserier'!$S$7:$AG$7,0)),"ikke funnet")} -> 1985610 | N31: =M31*(SUM(sys_næring_nas[2023])/SUM(sys_næring_nas[2022])) -> 2004764.9 | O31: =N31*(SUM(sys_næring_nas[2024])/SUM(sys_næring_nas[2023])) -> 2017453.8
B33: Telemark - Normalisert
B34: =B28 -> Totalt for næringer | C34: =C28/$C28 -> 1 | D34: =D28/$C28 -> 1.0390092 | E34: =E28/$C28 -> 1.0786656 | F34: =F28/$C28 -> 1.098229 | G34: =G28/$C28 -> 1.1395917 | H34: =H28/$C28 -> 1.1802483 | I34: =I28/$C28 -> 1.2427042 | J34: =J28/$C28 -> 1.3125441 | ... O34: =O28/$C28 -> 1.508283
B36: Landet uten sokkelen - normalisert
B37: =B31 -> Totalt for næringer | C37: =C31/$C31 -> 1 | D37: =D31/$C31 -> 1.056994 | E37: =E31/$C31 -> 1.1018563 | F37: =F31/$C31 -> 1.1492839 | G37: =G31/$C31 -> 1.168686 | H37: =H31/$C31 -> 1.2068969 | I37: =I31/$C31 -> 1.2678368 | J37: =J31/$C31 -> 1.3405393 | ... O37: =O31/$C31 -> 1.5707388
B42: Tabell til rapport (Thinkcell)
C44: 2012 | D44: 2013 | E44: 2014 | F44: 2015 | G44: 2016 | H44: 2017 | I44: 2018 | J44: 2019 | K44: 2020 | L44: 2021 | M44: 2022 | N44: 2023 | O44: 2024
Y45: Sysselsetting - Telemark | Z45: Sysselsetting - landet uten sokkelen
B46: Verdiskapning - Telemark | C46: =C16 -> 1 | D46: =D16 -> 1.0471145 | E46: =E16 -> 1.0837842 | F46: =F16 -> 1.1711377 | G46: =G16 -> 1.1730162 | H46: =H16 -> 1.2287534 | I46: =I16 -> 1.3295011 | J46: =J16 -> 1.3683874 | ... O46: =O16 -> 1.6455068 | X46: 2012 | Y46: 100 | Z46: 100
B47: Sysselsetting - Telemark | C47: =C34 -> 1 | D47: =D34 -> 1.0390092 | E47: =E34 -> 1.0786656 | F47: =F34 -> 1.098229 | G47: =G34 -> 1.1395917 | H47: =H34 -> 1.1802483 | I47: =I34 -> 1.2427042 | J47: =J34 -> 1.3125441 | ... O47: =O34 -> 1.508283 | Q47: Ikke korrekte tall, se mailer med Brage i august 2026 | X47: 2013 | Y47: 100 | Z47: 101
B48: Verdiskapning - Landet uten sokkelen | C48: =C19 -> 1 | D48: =D19 -> 1.0574756 | E48: =E19 -> 1.1092874 | F48: =F19 -> 1.1533171 | G48: =G19 -> 1.1818478 | H48: =H19 -> 1.2238381 | I48: =I19 -> 1.2789814 | J48: =J19 -> 1.3459929 | ... O48: =O19 -> 1.7625552 | X48: 2014 | Y48: 100 | Z48: 102
B49: Sysselsetting - landet uten sokkelen | C49: =C37 -> 1 | D49: =D37 -> 1.056994 | E49: =E37 -> 1.1018563 | F49: =F37 -> 1.1492839 | G49: =G37 -> 1.168686 | H49: =H37 -> 1.2068969 | I49: =I37 -> 1.2678368 | J49: =J37 -> 1.3405393 | ... O49: =O37 -> 1.5707388 | Q49: Ikke korrekte tall, se mailer med Brage i august 2026 | X49: 2015 | Y49: 97 | Z49: 100
X50: 2016 | Y50: 98 | Z50: 101
X51: 2017 | Y51: 99 | Z51: 102
C52: 2012 | D52: 2013 | E52: 2014 | F52: 2015 | G52: 2016 | H52: 2017 | I52: 2018 | J52: 2019 | K52: 2020 | L52: 2021 | M52: 2022 | N52: 2023 | O52: 2024 | P52: 2025 | X52: 2018 | Y52: 99 | Z52: 104
B53: Sysselsetting - Telemark | C53: 1 | D53: 1 | E53: 1 | F53: 0.97 | G53: 0.98 | H53: 0.99 | I53: 0.99 | J53: 0.99 | K53: 0.99 | L53: 1.01 | M53: 1.01 | N53: 1.02 | O53: 1.03 | P53: 1.03 | X53: 2019 | Y53: 99 | Z53: 105
B54: Sysselsetting - landet uten sokkelen | C54: 1 | D54: 1.01 | E54: 1.02 | F54: 1 | G54: 1.01 | H54: 1.02 | I54: 1.04 | J54: 1.05 | K54: 1.04 | L54: 1.07 | M54: 1.09 | N54: 1.1 | O54: 1.11 | P54: 1.11 | X54: 2020 | Y54: 99 | Z54: 104
X55: 2021 | Y55: 101 | Z55: 107
B56: Sysselsatte (etter arbeidssted) | C56: 2012 | D56: 2013 | E56: 2014 | F56: 2015 | G56: 2016 | H56: 2017 | I56: 2018 | J56: 2019 | K56: 2020 | L56: 2021 | M56: 2022 | N56: 2023 | O56: 2024 | P56: 2025 | X56: 2022 | Y56: 101 | Z56: 109
B57: Telemark | C57: 76607 | D57: 76460 | E57: 76279 | F57: 74318 | G57: 75188 | H57: 75640 | I57: 75752 | J57: 76180 | K57: 75756 | L57: 77084 | M57: 77563 | N57: 78308 | O57: 78849 | P57: 78850 | X57: 2023 | Y57: 102 | Z57: 110
B58: Landet uten Sokkelen | C58: 2570303 | D58: 2598397 | E58: 2629420 | F58: 2579221 | G58: 2598486 | H58: 2632555 | I58: 2674873 | J58: 2703670 | K58: 2674439 | L58: 2755217 | M58: 2811007 | N58: 2837948 | O58: 2855865 | P58: 2865382 | X58: 2024 | Y58: 103 | Z58: 111

Sheet FNR Telemark estimert
B2: Fylkesfordelt nasjonalregnskap - estimat og fremskrivning
C5: 2018 | D5: 2019 | E5: 2020 | F5: 2021 | G5: 2022 | H5: 2023 | I5: 2024
B6: 08 Telemark (-2019)
B7: Helse- og omsorgstjenester | C7: {=_xlfn.XLOOKUP($B$6&$B7,'FNR tidsserier'!$B$7:$B$182&'FNR tidsserier'!$C$7:$C$182,INDEX('FNR tidsserier'!$D$7:$R$182,,MATCH(C$5,'FNR tidsserier'!$D$7:$R$7,0)),"ikke funnet")} -> 11708 | D7: {=_xlfn.XLOOKUP($B$6&$B7,'FNR tidsserier'!$B$7:$B$182&'FNR tidsserier'!$C$7:$C$182,INDEX('FNR tidsserier'!$D$7:$R$182,,MATCH(D$5,'FNR tidsserier'!$D$7:$R$7,0)),"ikke funnet")} -> 12046 | E7: {=_xlfn.XLOOKUP($B$6&$B7,'FNR tidsserier'!$B$7:$B$182&'FNR tidsserier'!$C$7:$C$182,INDEX('FNR tidsserier'!$D$7:$R$182,,MATCH(E$5,'FNR tidsserier'!$D$7:$R$7,0)),"ikke funnet")} -> 12005.999 | F7: {=_xlfn.XLOOKUP($B$6&$B7,'FNR tidsserier'!$B$7:$B$182&'FNR tidsserier'!$C$7:$C$182,INDEX('FNR tidsserier'!$D$7:$R$182,,MATCH(F$5,'FNR tidsserier'!$D$7:$R$7,0)),"ikke funnet")} -> 12733.049 | G7: {=_xlfn.XLOOKUP($B$6&$B7,'FNR tidsserier'!$B$7:$B$182&'FNR tidsserier'!$C$7:$C$182,INDEX('FNR tidsserier'!$D$7:$R$182,,MATCH(G$5,'FNR tidsserier'!$D$7:$R$7,0)),"ikke funnet")} -> 13726.479 | H7: =IFERROR(G7*_xlfn.XLOOKUP($B7,$B$96:$B$117,$C$96:$C$117),0) -> 14714.222 | I7: =IFERROR(H7*_xlfn.XLOOKUP($B7,$B$96:$B$117,$D$96:$D$117),0) -> 14978.909
B8: Industri | C8: {=_xlfn.XLOOKUP($B$6&$B8,'FNR tidsserier'!$B$7:$B$182&'FNR tidsserier'!$C$7:$C$182,INDEX('FNR tidsserier'!$D$7:$R$182,,MATCH(C$5,'FNR tidsserier'!$D$7:$R$7,0)),"ikke funnet")} -> 9370 | D8: {=_xlfn.XLOOKUP($B$6&$B8,'FNR tidsserier'!$B$7:$B$182&'FNR tidsserier'!$C$7:$C$182,INDEX('FNR tidsserier'!$D$7:$R$182,,MATCH(D$5,'FNR tidsserier'!$D$7:$R$7,0)),"ikke funnet")} -> 10055 | E8: {=_xlfn.XLOOKUP($B$6&$B8,'FNR tidsserier'!$B$7:$B$182&'FNR tidsserier'!$C$7:$C$182,INDEX('FNR tidsserier'!$D$7:$R$182,,MATCH(E$5,'FNR tidsserier'!$D$7:$R$7,0)),"ikke funnet")} -> 9918.2753 | F8: {=_xlfn.XLOOKUP($B$6&$B8,'FNR tidsserier'!$B$7:$B$182&'FNR tidsserier'!$C$7:$C$182,INDEX('FNR tidsserier'!$D$7:$R$182,,MATCH(F$5,'FNR tidsserier'!$D$7:$R$7,0)),"ikke funnet")} -> 10857.706 | G8: {=_xlfn.XLOOKUP($B$6&$B8,'FNR tidsserier'!$B$7:$B$182&'FNR tidsserier'!$C$7:$C$182,INDEX('FNR tidsserier'!$D$7:$R$182,,MATCH(G$5,'FNR tidsserier'!$D$7:$R$7,0)),"ikke funnet")} -> 11377.26 | H8: =IFERROR(G8*_xlfn.XLOOKUP($B8,$B$96:$B$117,$C$96:$C$117),0) -> 10866.449 | I8: =IFERROR(H8*_xlfn.XLOOKUP($B8,$B$96:$B$117,$D$96:$D$117),0) -> 11105.872
B9: Varehandel og reparasjon av motorvogner | C9: {=_xlfn.XLOOKUP($B$6&$B9,'FNR tidsserier'!$B$7:$B$182&'FNR tidsserier'!$C$7:$C$182,INDEX('FNR tidsserier'!$D$7:$R$182,,MATCH(C$5,'FNR tidsserier'!$D$7:$R$7,0)),"ikke funnet")} -> 6494 | D9: {=_xlfn.XLOOKUP($B$6&$B9,'FNR tidsserier'!$B$7:$B$182&'FNR tidsserier'!$C$7:$C$182,INDEX('FNR tidsserier'!$D$7:$R$182,,MATCH(D$5,'FNR tidsserier'!$D$7:$R$7,0)),"ikke funnet")} -> 6543 | E9: {=_xlfn.XLOOKUP($B$6&$B9,'FNR tidsserier'!$B$7:$B$182&'FNR tidsserier'!$C$7:$C$182,INDEX('FNR tidsserier'!$D$7:$R$182,,MATCH(E$5,'FNR tidsserier'!$D$7:$R$7,0)),"ikke funnet")} -> 7271.9079 | F9: {=_xlfn.XLOOKUP($B$6&$B9,'FNR tidsserier'!$B$7:$B$182&'FNR tidsserier'!$C$7:$C$182,INDEX('FNR tidsserier'!$D$7:$R$182,,MATCH(F$5,'FNR tidsserier'!$D$7:$R$7,0)),"ikke funnet")} -> 8057.2361 | G9: {=_xlfn.XLOOKUP($B$6&$B9,'FNR tidsserier'!$B$7:$B$182&'FNR tidsserier'!$C$7:$C$182,INDEX('FNR tidsserier'!$D$7:$R$182,,MATCH(G$5,'FNR tidsserier'!$D$7:$R$7,0)),"ikke funnet")} -> 7846.2734 | H9: =IFERROR(G9*_xlfn.XLOOKUP($B9,$B$96:$B$117,$C$96:$C$117),0) -> 7995.4345 | I9: =IFERROR(H9*_xlfn.XLOOKUP($B9,$B$96:$B$117,$D$96:$D$117),0) -> 7905.8283
B10: Bygge- og anleggsvirksomhet | C10: {=_xlfn.XLOOKUP($B$6&$B10,'FNR tidsserier'!$B$7:$B$182&'FNR tidsserier'!$C$7:$C$182,INDEX('FNR tidsserier'!$D$7:$R$182,,MATCH(C$5,'FNR tidsserier'!$D$7:$R$7,0)),"ikke funnet")} -> 6082 | D10: {=_xlfn.XLOOKUP($B$6&$B10,'FNR tidsserier'!$B$7:$B$182&'FNR tidsserier'!$C$7:$C$182,INDEX('FNR tidsserier'!$D$7:$R$182,,MATCH(D$5,'FNR tidsserier'!$D$7:$R$7,0)),"ikke funnet")} -> 6392 | E10: {=_xlfn.XLOOKUP($B$6&$B10,'FNR tidsserier'!$B$7:$B$182&'FNR tidsserier'!$C$7:$C$182,INDEX('FNR tidsserier'!$D$7:$R$182,,MATCH(E$5,'FNR tidsserier'!$D$7:$R$7,0)),"ikke funnet")} -> 6363.4974 | F10: {=_xlfn.XLOOKUP($B$6&$B10,'FNR tidsserier'!$B$7:$B$182&'FNR tidsserier'!$C$7:$C$182,INDEX('FNR tidsserier'!$D$7:$R$182,,MATCH(F$5,'FNR tidsserier'!$D$7:$R$7,0)),"ikke funnet")} -> 6756.6771 | G10: {=_xlfn.XLOOKUP($B$6&$B10,'FNR tidsserier'!$B$7:$B$182&'FNR tidsserier'!$C$7:$C$182,INDEX('FNR tidsserier'!$D$7:$R$182,,MATCH(G$5,'FNR tidsserier'!$D$7:$R$7,0)),"ikke funnet")} -> 7291.1983 | H10: =IFERROR(G10*_xlfn.XLOOKUP($B10,$B$96:$B$117,$C$96:$C$117),0) -> 6981.3748 | I10: =IFERROR(H10*_xlfn.XLOOKUP($B10,$B$96:$B$117,$D$96:$D$117),0) -> 6838.1769
B11: Undervisning | C11: {=_xlfn.XLOOKUP($B$6&$B11,'FNR tidsserier'!$B$7:$B$182&'FNR tidsserier'!$C$7:$C$182,INDEX('FNR tidsserier'!$D$7:$R$182,,MATCH(C$5,'FNR tidsserier'!$D$7:$R$7,0)),"ikke funnet")} -> 4990 | D11: {=_xlfn.XLOOKUP($B$6&$B11,'FNR tidsserier'!$B$7:$B$182&'FNR tidsserier'!$C$7:$C$182,INDEX('FNR tidsserier'!$D$7:$R$182,,MATCH(D$5,'FNR tidsserier'!$D$7:$R$7,0)),"ikke funnet")} -> 5175 | E11: {=_xlfn.XLOOKUP($B$6&$B11,'FNR tidsserier'!$B$7:$B$182&'FNR tidsserier'!$C$7:$C$182,INDEX('FNR tidsserier'!$D$7:$R$182,,MATCH(E$5,'FNR tidsserier'!$D$7:$R$7,0)),"ikke funnet")} -> 5044.3672 | F11: {=_xlfn.XLOOKUP($B$6&$B11,'FNR tidsserier'!$B$7:$B$182&'FNR tidsserier'!$C$7:$C$182,INDEX('FNR tidsserier'!$D$7:$R$182,,MATCH(F$5,'FNR tidsserier'!$D$7:$R$7,0)),"ikke funnet")} -> 5343.1456 | G11: {=_xlfn.XLOOKUP($B$6&$B11,'FNR tidsserier'!$B$7:$B$182&'FNR tidsserier'!$C$7:$C$182,INDEX('FNR tidsserier'!$D$7:$R$182,,MATCH(G$5,'FNR tidsserier'!$D$7:$R$7,0)),"ikke funnet")} -> 5882.8885 | H11: =IFERROR(G11*_xlfn.XLOOKUP($B11,$B$96:$B$117,$C$96:$C$117),0) -> 6306.2147 | I11: =IFERROR(H11*_xlfn.XLOOKUP($B11,$B$96:$B$117,$D$96:$D$117),0) -> 6284.844
B12: Offentlig administrasjon og forsvar | C12: {=_xlfn.XLOOKUP($B$6&$B12,'FNR tidsserier'!$B$7:$B$182&'FNR tidsserier'!$C$7:$C$182,INDEX('FNR tidsserier'!$D$7:$R$182,,MATCH(C$5,'FNR tidsserier'!$D$7:$R$7,0)),"ikke funnet")} -> 4635 | D12: {=_xlfn.XLOOKUP($B$6&$B12,'FNR tidsserier'!$B$7:$B$182&'FNR tidsserier'!$C$7:$C$182,INDEX('FNR tidsserier'!$D$7:$R$182,,MATCH(D$5,'FNR tidsserier'!$D$7:$R$7,0)),"ikke funnet")} -> 4833 | E12: {=_xlfn.XLOOKUP($B$6&$B12,'FNR tidsserier'!$B$7:$B$182&'FNR tidsserier'!$C$7:$C$182,INDEX('FNR tidsserier'!$D$7:$R$182,,MATCH(E$5,'FNR tidsserier'!$D$7:$R$7,0)),"ikke funnet")} -> 5119.9232 | F12: {=_xlfn.XLOOKUP($B$6&$B12,'FNR tidsserier'!$B$7:$B$182&'FNR tidsserier'!$C$7:$C$182,INDEX('FNR tidsserier'!$D$7:$R$182,,MATCH(F$5,'FNR tidsserier'!$D$7:$R$7,0)),"ikke funnet")} -> 5381.3067 | G12: {=_xlfn.XLOOKUP($B$6&$B12,'FNR tidsserier'!$B$7:$B$182&'FNR tidsserier'!$C$7:$C$182,INDEX('FNR tidsserier'!$D$7:$R$182,,MATCH(G$5,'FNR tidsserier'!$D$7:$R$7,0)),"ikke funnet")} -> 5603.9814 | H12: =IFERROR(G12*_xlfn.XLOOKUP($B12,$B$96:$B$117,$C$96:$C$117),0) -> 6007.2378 | I12: =IFERROR(H12*_xlfn.XLOOKUP($B12,$B$96:$B$117,$D$96:$D$117),0) -> 6043.334
B13: Elektrisitets-, gass- og varmtvannsforsyning | C13: {=_xlfn.XLOOKUP($B$6&$B13,'FNR tidsserier'!$B$7:$B$182&'FNR tidsserier'!$C$7:$C$182,INDEX('FNR tidsserier'!$D$7:$R$182,,MATCH(C$5,'FNR tidsserier'!$D$7:$R$7,0)),"ikke funnet")} -> 7098 | D13: {=_xlfn.XLOOKUP($B$6&$B13,'FNR tidsserier'!$B$7:$B$182&'FNR tidsserier'!$C$7:$C$182,INDEX('FNR tidsserier'!$D$7:$R$182,,MATCH(D$5,'FNR tidsserier'!$D$7:$R$7,0)),"ikke funnet")} -> 6298 | E13: =E$54*(E$41/E$44) -> 6992.1105 | F13: =F$54*(F$41/F$44) -> 10763.97 | G13: =G$54*(G$41/G$44) -> 14663.381 | H13: =IFERROR(G13*_xlfn.XLOOKUP($B13,$B$96:$B$117,$C$96:$C$117),0) -> 10371.708 | I13: =IFERROR(H13*_xlfn.XLOOKUP($B13,$B$96:$B$117,$D$96:$D$117),0) -> 10674.402
B14: Faglig, vitenskapelig og teknisk tjenesteyting | C14: {=_xlfn.XLOOKUP($B$6&$B14,'FNR tidsserier'!$B$7:$B$182&'FNR tidsserier'!$C$7:$C$182,INDEX('FNR tidsserier'!$D$7:$R$182,,MATCH(C$5,'FNR tidsserier'!$D$7:$R$7,0)),"ikke funnet")} -> 3712 | D14: {=_xlfn.XLOOKUP($B$6&$B14,'FNR tidsserier'!$B$7:$B$182&'FNR tidsserier'!$C$7:$C$182,INDEX('FNR tidsserier'!$D$7:$R$182,,MATCH(D$5,'FNR tidsserier'!$D$7:$R$7,0)),"ikke funnet")} -> 3581 | E14: {=_xlfn.XLOOKUP($B$6&$B14,'FNR tidsserier'!$B$7:$B$182&'FNR tidsserier'!$C$7:$C$182,INDEX('FNR tidsserier'!$D$7:$R$182,,MATCH(E$5,'FNR tidsserier'!$D$7:$R$7,0)),"ikke funnet")} -> 3466.7742 | F14: {=_xlfn.XLOOKUP($B$6&$B14,'FNR tidsserier'!$B$7:$B$182&'FNR tidsserier'!$C$7:$C$182,INDEX('FNR tidsserier'!$D$7:$R$182,,MATCH(F$5,'FNR tidsserier'!$D$7:$R$7,0)),"ikke funnet")} -> 4333.4678 | G14: {=_xlfn.XLOOKUP($B$6&$B14,'FNR tidsserier'!$B$7:$B$182&'FNR tidsserier'!$C$7:$C$182,INDEX('FNR tidsserier'!$D$7:$R$182,,MATCH(G$5,'FNR tidsserier'!$D$7:$R$7,0)),"ikke funnet")} -> 5056.6013 | H14: =IFERROR(G14*_xlfn.XLOOKUP($B14,$B$96:$B$117,$C$96:$C$117),0) -> 4121.7865 | I14: =IFERROR(H14*_xlfn.XLOOKUP($B14,$B$96:$B$117,$D$96:$D$117),0) -> 4330.1549
B15: Boligtjenester, egen bolig | C15: {=_xlfn.XLOOKUP($B$6&$B15,'FNR tidsserier'!$B$7:$B$182&'FNR tidsserier'!$C$7:$C$182,INDEX('FNR tidsserier'!$D$7:$R$182,,MATCH(C$5,'FNR tidsserier'!$D$7:$R$7,0)),"ikke funnet")} -> 4635 | D15: {=_xlfn.XLOOKUP($B$6&$B15,'FNR tidsserier'!$B$7:$B$182&'FNR tidsserier'!$C$7:$C$182,INDEX('FNR tidsserier'!$D$7:$R$182,,MATCH(D$5,'FNR tidsserier'!$D$7:$R$7,0)),"ikke funnet")} -> 4984 | E15: {=_xlfn.XLOOKUP($B$6&$B15,'FNR tidsserier'!$B$7:$B$182&'FNR tidsserier'!$C$7:$C$182,INDEX('FNR tidsserier'!$D$7:$R$182,,MATCH(E$5,'FNR tidsserier'!$D$7:$R$7,0)),"ikke funnet")} -> 4690.4358 | F15: {=_xlfn.XLOOKUP($B$6&$B15,'FNR tidsserier'!$B$7:$B$182&'FNR tidsserier'!$C$7:$C$182,INDEX('FNR tidsserier'!$D$7:$R$182,,MATCH(F$5,'FNR tidsserier'!$D$7:$R$7,0)),"ikke funnet")} -> 5064.862 | G15: {=_xlfn.XLOOKUP($B$6&$B15,'FNR tidsserier'!$B$7:$B$182&'FNR tidsserier'!$C$7:$C$182,INDEX('FNR tidsserier'!$D$7:$R$182,,MATCH(G$5,'FNR tidsserier'!$D$7:$R$7,0)),"ikke funnet")} -> 6201.3248 | H15: =IFERROR(G15*_xlfn.XLOOKUP($B15,$B$96:$B$117,$C$96:$C$117),0) -> 6134.9109 | I15: =IFERROR(H15*_xlfn.XLOOKUP($B15,$B$96:$B$117,$D$96:$D$117),0) -> 5915.3457
B16: Forretningsmessig tjenesteyting | C16: {=_xlfn.XLOOKUP($B$6&$B16,'FNR tidsserier'!$B$7:$B$182&'FNR tidsserier'!$C$7:$C$182,INDEX('FNR tidsserier'!$D$7:$R$182,,MATCH(C$5,'FNR tidsserier'!$D$7:$R$7,0)),"ikke funnet")} -> 1558 | D16: {=_xlfn.XLOOKUP($B$6&$B16,'FNR tidsserier'!$B$7:$B$182&'FNR tidsserier'!$C$7:$C$182,INDEX('FNR tidsserier'!$D$7:$R$182,,MATCH(D$5,'FNR tidsserier'!$D$7:$R$7,0)),"ikke funnet")} -> 1841 | E16: {=_xlfn.XLOOKUP($B$6&$B16,'FNR tidsserier'!$B$7:$B$182&'FNR tidsserier'!$C$7:$C$182,INDEX('FNR tidsserier'!$D$7:$R$182,,MATCH(E$5,'FNR tidsserier'!$D$7:$R$7,0)),"ikke funnet")} -> 1686.5911 | F16: {=_xlfn.XLOOKUP($B$6&$B16,'FNR tidsserier'!$B$7:$B$182&'FNR tidsserier'!$C$7:$C$182,INDEX('FNR tidsserier'!$D$7:$R$182,,MATCH(F$5,'FNR tidsserier'!$D$7:$R$7,0)),"ikke funnet")} -> 1746.8951 | G16: {=_xlfn.XLOOKUP($B$6&$B16,'FNR tidsserier'!$B$7:$B$182&'FNR tidsserier'!$C$7:$C$182,INDEX('FNR tidsserier'!$D$7:$R$182,,MATCH(G$5,'FNR tidsserier'!$D$7:$R$7,0)),"ikke funnet")} -> 1927.807 | H16: =IFERROR(G16*_xlfn.XLOOKUP($B16,$B$96:$B$117,$C$96:$C$117),0) -> 1815.5031 | I16: =IFERROR(H16*_xlfn.XLOOKUP($B16,$B$96:$B$117,$D$96:$D$117),0) -> 1846.0108
B17: Kultur, underholdning og annen tjenesteyting | C17: {=_xlfn.XLOOKUP($B$6&$B17,'FNR tidsserier'!$B$7:$B$182&'FNR tidsserier'!$C$7:$C$182,INDEX('FNR tidsserier'!$D$7:$R$182,,MATCH(C$5,'FNR tidsserier'!$D$7:$R$7,0)),"ikke funnet")} -> 1455 | D17: {=_xlfn.XLOOKUP($B$6&$B17,'FNR tidsserier'!$B$7:$B$182&'FNR tidsserier'!$C$7:$C$182,INDEX('FNR tidsserier'!$D$7:$R$182,,MATCH(D$5,'FNR tidsserier'!$D$7:$R$7,0)),"ikke funnet")} -> 1600 | E17: {=_xlfn.XLOOKUP($B$6&$B17,'FNR tidsserier'!$B$7:$B$182&'FNR tidsserier'!$C$7:$C$182,INDEX('FNR tidsserier'!$D$7:$R$182,,MATCH(E$5,'FNR tidsserier'!$D$7:$R$7,0)),"ikke funnet")} -> 1437.7542 | F17: {=_xlfn.XLOOKUP($B$6&$B17,'FNR tidsserier'!$B$7:$B$182&'FNR tidsserier'!$C$7:$C$182,INDEX('FNR tidsserier'!$D$7:$R$182,,MATCH(F$5,'FNR tidsserier'!$D$7:$R$7,0)),"ikke funnet")} -> 1565.6259 | G17: {=_xlfn.XLOOKUP($B$6&$B17,'FNR tidsserier'!$B$7:$B$182&'FNR tidsserier'!$C$7:$C$182,INDEX('FNR tidsserier'!$D$7:$R$182,,MATCH(G$5,'FNR tidsserier'!$D$7:$R$7,0)),"ikke funnet")} -> 1739.788 | H17: =IFERROR(G17*_xlfn.XLOOKUP($B17,$B$96:$B$117,$C$96:$C$117),0) -> 1912.5832 | I17: =IFERROR(H17*_xlfn.XLOOKUP($B17,$B$96:$B$117,$D$96:$D$117),0) -> 1907.9951
B18: Informasjon og kommunikasjon | C18: {=_xlfn.XLOOKUP($B$6&$B18,'FNR tidsserier'!$B$7:$B$182&'FNR tidsserier'!$C$7:$C$182,INDEX('FNR tidsserier'!$D$7:$R$182,,MATCH(C$5,'FNR tidsserier'!$D$7:$R$7,0)),"ikke funnet")} -> 1453 | D18: {=_xlfn.XLOOKUP($B$6&$B18,'FNR tidsserier'!$B$7:$B$182&'FNR tidsserier'!$C$7:$C$182,INDEX('FNR tidsserier'!$D$7:$R$182,,MATCH(D$5,'FNR tidsserier'!$D$7:$R$7,0)),"ikke funnet")} -> 1489 | E18: =E54*(E$42/E$44) -> 1465.0874 | F18: =F54*(F$42/F$44) -> 1442.313 | G18: =G54*(G$42/G$44) -> 1267.0713 | H18: =IFERROR(G18*_xlfn.XLOOKUP($B18,$B$96:$B$117,$C$96:$C$117),0) -> 1408.5385 | I18: =IFERROR(H18*_xlfn.XLOOKUP($B18,$B$96:$B$117,$D$96:$D$117),0) -> 1503.9457
B19: Finansierings- og forsikringsvirksomhet | C19: {=_xlfn.XLOOKUP($B$6&$B19,'FNR tidsserier'!$B$7:$B$182&'FNR tidsserier'!$C$7:$C$182,INDEX('FNR tidsserier'!$D$7:$R$182,,MATCH(C$5,'FNR tidsserier'!$D$7:$R$7,0)),"ikke funnet")} -> 1827 | D19: {=_xlfn.XLOOKUP($B$6&$B19,'FNR tidsserier'!$B$7:$B$182&'FNR tidsserier'!$C$7:$C$182,INDEX('FNR tidsserier'!$D$7:$R$182,,MATCH(D$5,'FNR tidsserier'!$D$7:$R$7,0)),"ikke funnet")} -> 1736 | E19: {=_xlfn.XLOOKUP($B$6&$B19,'FNR tidsserier'!$B$7:$B$182&'FNR tidsserier'!$C$7:$C$182,INDEX('FNR tidsserier'!$D$7:$R$182,,MATCH(E$5,'FNR tidsserier'!$D$7:$R$7,0)),"ikke funnet")} -> 2005.8722 | F19: {=_xlfn.XLOOKUP($B$6&$B19,'FNR tidsserier'!$B$7:$B$182&'FNR tidsserier'!$C$7:$C$182,INDEX('FNR tidsserier'!$D$7:$R$182,,MATCH(F$5,'FNR tidsserier'!$D$7:$R$7,0)),"ikke funnet")} -> 2035.9118 | G19: {=_xlfn.XLOOKUP($B$6&$B19,'FNR tidsserier'!$B$7:$B$182&'FNR tidsserier'!$C$7:$C$182,INDEX('FNR tidsserier'!$D$7:$R$182,,MATCH(G$5,'FNR tidsserier'!$D$7:$R$7,0)),"ikke funnet")} -> 2015.0779 | H19: =IFERROR(G19*_xlfn.XLOOKUP($B19,$B$96:$B$117,$C$96:$C$117),0) -> 2393.5033 | I19: =IFERROR(H19*_xlfn.XLOOKUP($B19,$B$96:$B$117,$D$96:$D$117),0) -> 2809.4235
B20: Omsetning og drift av fast eiendom | C20: {=_xlfn.XLOOKUP($B$6&$B20,'FNR tidsserier'!$B$7:$B$182&'FNR tidsserier'!$C$7:$C$182,INDEX('FNR tidsserier'!$D$7:$R$182,,MATCH(C$5,'FNR tidsserier'!$D$7:$R$7,0)),"ikke funnet")} -> 1134 | D20: {=_xlfn.XLOOKUP($B$6&$B20,'FNR tidsserier'!$B$7:$B$182&'FNR tidsserier'!$C$7:$C$182,INDEX('FNR tidsserier'!$D$7:$R$182,,MATCH(D$5,'FNR tidsserier'!$D$7:$R$7,0)),"ikke funnet")} -> 1375 | E20: {=_xlfn.XLOOKUP($B$6&$B20,'FNR tidsserier'!$B$7:$B$182&'FNR tidsserier'!$C$7:$C$182,INDEX('FNR tidsserier'!$D$7:$R$182,,MATCH(E$5,'FNR tidsserier'!$D$7:$R$7,0)),"ikke funnet")} -> 1320 | F20: {=_xlfn.XLOOKUP($B$6&$B20,'FNR tidsserier'!$B$7:$B$182&'FNR tidsserier'!$C$7:$C$182,INDEX('FNR tidsserier'!$D$7:$R$182,,MATCH(F$5,'FNR tidsserier'!$D$7:$R$7,0)),"ikke funnet")} -> 1401.9677 | G20: {=_xlfn.XLOOKUP($B$6&$B20,'FNR tidsserier'!$B$7:$B$182&'FNR tidsserier'!$C$7:$C$182,INDEX('FNR tidsserier'!$D$7:$R$182,,MATCH(G$5,'FNR tidsserier'!$D$7:$R$7,0)),"ikke funnet")} -> 1521.5484 | H20: =IFERROR(G20*_xlfn.XLOOKUP($B20,$B$96:$B$117,$C$96:$C$117),0) -> 1367.7174 | I20: =IFERROR(H20*_xlfn.XLOOKUP($B20,$B$96:$B$117,$D$96:$D$117),0) -> 1381.061
B21: Overnattings- og serveringsvirksomhet | C21: {=_xlfn.XLOOKUP($B$6&$B21,'FNR tidsserier'!$B$7:$B$182&'FNR tidsserier'!$C$7:$C$182,INDEX('FNR tidsserier'!$D$7:$R$182,,MATCH(C$5,'FNR tidsserier'!$D$7:$R$7,0)),"ikke funnet")} -> 936 | D21: {=_xlfn.XLOOKUP($B$6&$B21,'FNR tidsserier'!$B$7:$B$182&'FNR tidsserier'!$C$7:$C$182,INDEX('FNR tidsserier'!$D$7:$R$182,,MATCH(D$5,'FNR tidsserier'!$D$7:$R$7,0)),"ikke funnet")} -> 1025 | E21: {=_xlfn.XLOOKUP($B$6&$B21,'FNR tidsserier'!$B$7:$B$182&'FNR tidsserier'!$C$7:$C$182,INDEX('FNR tidsserier'!$D$7:$R$182,,MATCH(E$5,'FNR tidsserier'!$D$7:$R$7,0)),"ikke funnet")} -> 748.99264 | F21: {=_xlfn.XLOOKUP($B$6&$B21,'FNR tidsserier'!$B$7:$B$182&'FNR tidsserier'!$C$7:$C$182,INDEX('FNR tidsserier'!$D$7:$R$182,,MATCH(F$5,'FNR tidsserier'!$D$7:$R$7,0)),"ikke funnet")} -> 986.87524 | G21: {=_xlfn.XLOOKUP($B$6&$B21,'FNR tidsserier'!$B$7:$B$182&'FNR tidsserier'!$C$7:$C$182,INDEX('FNR tidsserier'!$D$7:$R$182,,MATCH(G$5,'FNR tidsserier'!$D$7:$R$7,0)),"ikke funnet")} -> 1277.9737 | H21: =IFERROR(G21*_xlfn.XLOOKUP($B21,$B$96:$B$117,$C$96:$C$117),0) -> 1417.0843 | I21: =IFERROR(H21*_xlfn.XLOOKUP($B21,$B$96:$B$117,$D$96:$D$117),0) -> 1396.5468
B22: Vannforsyning, avløp og renovasjon | C22: {=_xlfn.XLOOKUP($B$6&$B22,'FNR tidsserier'!$B$7:$B$182&'FNR tidsserier'!$C$7:$C$182,INDEX('FNR tidsserier'!$D$7:$R$182,,MATCH(C$5,'FNR tidsserier'!$D$7:$R$7,0)),"ikke funnet")} -> 851 | D22: {=_xlfn.XLOOKUP($B$6&$B22,'FNR tidsserier'!$B$7:$B$182&'FNR tidsserier'!$C$7:$C$182,INDEX('FNR tidsserier'!$D$7:$R$182,,MATCH(D$5,'FNR tidsserier'!$D$7:$R$7,0)),"ikke funnet")} -> 929 | E22: {=_xlfn.XLOOKUP($B$6&$B22,'FNR tidsserier'!$B$7:$B$182&'FNR tidsserier'!$C$7:$C$182,INDEX('FNR tidsserier'!$D$7:$R$182,,MATCH(E$5,'FNR tidsserier'!$D$7:$R$7,0)),"ikke funnet")} -> 1118.5735 | F22: {=_xlfn.XLOOKUP($B$6&$B22,'FNR tidsserier'!$B$7:$B$182&'FNR tidsserier'!$C$7:$C$182,INDEX('FNR tidsserier'!$D$7:$R$182,,MATCH(F$5,'FNR tidsserier'!$D$7:$R$7,0)),"ikke funnet")} -> 1334.6514 | G22: {=_xlfn.XLOOKUP($B$6&$B22,'FNR tidsserier'!$B$7:$B$182&'FNR tidsserier'!$C$7:$C$182,INDEX('FNR tidsserier'!$D$7:$R$182,,MATCH(G$5,'FNR tidsserier'!$D$7:$R$7,0)),"ikke funnet")} -> 1342.7374 | H22: =IFERROR(G22*_xlfn.XLOOKUP($B22,$B$96:$B$117,$C$96:$C$117),0) -> 1322.5665 | I22: =IFERROR(H22*_xlfn.XLOOKUP($B22,$B$96:$B$117,$D$96:$D$117),0) -> 1278.0765
B23: Jordbruk og skogbruk | C23: {=_xlfn.XLOOKUP($B$6&$B23,'FNR tidsserier'!$B$7:$B$182&'FNR tidsserier'!$C$7:$C$182,INDEX('FNR tidsserier'!$D$7:$R$182,,MATCH(C$5,'FNR tidsserier'!$D$7:$R$7,0)),"ikke funnet")} -> 569 | D23: {=_xlfn.XLOOKUP($B$6&$B23,'FNR tidsserier'!$B$7:$B$182&'FNR tidsserier'!$C$7:$C$182,INDEX('FNR tidsserier'!$D$7:$R$182,,MATCH(D$5,'FNR tidsserier'!$D$7:$R$7,0)),"ikke funnet")} -> 716 | E23: {=_xlfn.XLOOKUP($B$6&$B23,'FNR tidsserier'!$B$7:$B$182&'FNR tidsserier'!$C$7:$C$182,INDEX('FNR tidsserier'!$D$7:$R$182,,MATCH(E$5,'FNR tidsserier'!$D$7:$R$7,0)),"ikke funnet")} -> 731.90072 | F23: {=_xlfn.XLOOKUP($B$6&$B23,'FNR tidsserier'!$B$7:$B$182&'FNR tidsserier'!$C$7:$C$182,INDEX('FNR tidsserier'!$D$7:$R$182,,MATCH(F$5,'FNR tidsserier'!$D$7:$R$7,0)),"ikke funnet")} -> 788.95624 | G23: {=_xlfn.XLOOKUP($B$6&$B23,'FNR tidsserier'!$B$7:$B$182&'FNR tidsserier'!$C$7:$C$182,INDEX('FNR tidsserier'!$D$7:$R$182,,MATCH(G$5,'FNR tidsserier'!$D$7:$R$7,0)),"ikke funnet")} -> 876.41019 | H23: =IFERROR(G23*_xlfn.XLOOKUP($B23,$B$96:$B$117,$C$96:$C$117),0) -> 1000.5303 | I23: =IFERROR(H23*_xlfn.XLOOKUP($B23,$B$96:$B$117,$D$96:$D$117),0) -> 991.31866
B24: Bergverksdrift | C24: {=_xlfn.XLOOKUP($B$6&$B24,'FNR tidsserier'!$B$7:$B$182&'FNR tidsserier'!$C$7:$C$182,INDEX('FNR tidsserier'!$D$7:$R$182,,MATCH(C$5,'FNR tidsserier'!$D$7:$R$7,0)),"ikke funnet")} -> 186 | D24: {=_xlfn.XLOOKUP($B$6&$B24,'FNR tidsserier'!$B$7:$B$182&'FNR tidsserier'!$C$7:$C$182,INDEX('FNR tidsserier'!$D$7:$R$182,,MATCH(D$5,'FNR tidsserier'!$D$7:$R$7,0)),"ikke funnet")} -> 155 | E24: =E54*(E$43/E$44) -> 192.73963 | F24: =F54*(F$43/F$44) -> 163.42827 | G24: =G54*(G$43/G$44) -> 162.29135 | H24: =IFERROR(G24*_xlfn.XLOOKUP($B24,$B$96:$B$117,$C$96:$C$117),0) -> 327.73491 | I24: =IFERROR(H24*_xlfn.XLOOKUP($B24,$B$96:$B$117,$D$96:$D$117),0) -> 377.96249
B25: Utenriks sjøfart | C25: {=_xlfn.XLOOKUP($B$6&$B25,'FNR tidsserier'!$B$7:$B$182&'FNR tidsserier'!$C$7:$C$182,INDEX('FNR tidsserier'!$D$7:$R$182,,MATCH(C$5,'FNR tidsserier'!$D$7:$R$7,0)),"ikke funnet")} -> 14 | D25: {=_xlfn.XLOOKUP($B$6&$B25,'FNR tidsserier'!$B$7:$B$182&'FNR tidsserier'!$C$7:$C$182,INDEX('FNR tidsserier'!$D$7:$R$182,,MATCH(D$5,'FNR tidsserier'!$D$7:$R$7,0)),"ikke funnet")} -> 16 | E25: {=_xlfn.XLOOKUP($B$6&$B25,'FNR tidsserier'!$B$7:$B$182&'FNR tidsserier'!$C$7:$C$182,INDEX('FNR tidsserier'!$D$7:$R$182,,MATCH(E$5,'FNR tidsserier'!$D$7:$R$7,0)),"ikke funnet")} -> 5.2197483 | F25: {=_xlfn.XLOOKUP($B$6&$B25,'FNR tidsserier'!$B$7:$B$182&'FNR tidsserier'!$C$7:$C$182,INDEX('FNR tidsserier'!$D$7:$R$182,,MATCH(F$5,'FNR tidsserier'!$D$7:$R$7,0)),"ikke funnet")} -> 11.616651 | G25: {=_xlfn.XLOOKUP($B$6&$B25,'FNR tidsserier'!$B$7:$B$182&'FNR tidsserier'!$C$7:$C$182,INDEX('FNR tidsserier'!$D$7:$R$182,,MATCH(G$5,'FNR tidsserier'!$D$7:$R$7,0)),"ikke funnet")} -> 18.04453 | H25: =IFERROR(G25*_xlfn.XLOOKUP($B25,$B$96:$B$117,$C$96:$C$117),0) -> 24.768243 | I25: =IFERROR(H25*_xlfn.XLOOKUP($B25,$B$96:$B$117,$D$96:$D$117),0) -> 24.407977
B26: Rørtransport | C26: {=_xlfn.XLOOKUP($B$6&$B26,'FNR tidsserier'!$B$7:$B$182&'FNR tidsserier'!$C$7:$C$182,INDEX('FNR tidsserier'!$D$7:$R$182,,MATCH(C$5,'FNR tidsserier'!$D$7:$R$7,0)),"ikke funnet")} -> 0 | D26: {=_xlfn.XLOOKUP($B$6&$B26,'FNR tidsserier'!$B$7:$B$182&'FNR tidsserier'!$C$7:$C$182,INDEX('FNR tidsserier'!$D$7:$R$182,,MATCH(D$5,'FNR tidsserier'!$D$7:$R$7,0)),"ikke funnet")} -> 0 | E26: {=_xlfn.XLOOKUP($B$6&$B26,'FNR tidsserier'!$B$7:$B$182&'FNR tidsserier'!$C$7:$C$182,INDEX('FNR tidsserier'!$D$7:$R$182,,MATCH(E$5,'FNR tidsserier'!$D$7:$R$7,0)),"ikke funnet")} -> - | F26: {=_xlfn.XLOOKUP($B$6&$B26,'FNR tidsserier'!$B$7:$B$182&'FNR tidsserier'!$C$7:$C$182,INDEX('FNR tidsserier'!$D$7:$R$182,,MATCH(F$5,'FNR tidsserier'!$D$7:$R$7,0)),"ikke funnet")} -> - | G26: {=_xlfn.XLOOKUP($B$6&$B26,'FNR tidsserier'!$B$7:$B$182&'FNR tidsserier'!$C$7:$C$182,INDEX('FNR tidsserier'!$D$7:$R$182,,MATCH(G$5,'FNR tidsserier'!$D$7:$R$7,0)),"ikke funnet")} -> - | H26: =IFERROR(G26*_xlfn.XLOOKUP($B26,$B$96:$B$117,$C$96:$C$117),0) -> 0 | I26: =IFERROR(H26*_xlfn.XLOOKUP($B26,$B$96:$B$117,$D$96:$D$117),0) -> 0
B27: Post og distribusjonsvirksomhet | C27: {=_xlfn.XLOOKUP($B$6&$B27,'FNR tidsserier'!$B$7:$B$182&'FNR tidsserier'!$C$7:$C$182,INDEX('FNR tidsserier'!$D$7:$R$182,,MATCH(C$5,'FNR tidsserier'!$D$7:$R$7,0)),"ikke funnet")} -> 0 | D27: {=_xlfn.XLOOKUP($B$6&$B27,'FNR tidsserier'!$B$7:$B$182&'FNR tidsserier'!$C$7:$C$182,INDEX('FNR tidsserier'!$D$7:$R$182,,MATCH(D$5,'FNR tidsserier'!$D$7:$R$7,0)),"ikke funnet")} -> 0 | E27: {=_xlfn.XLOOKUP($B$6&$B27,'FNR tidsserier'!$B$7:$B$182&'FNR tidsserier'!$C$7:$C$182,INDEX('FNR tidsserier'!$D$7:$R$182,,MATCH(E$5,'FNR tidsserier'!$D$7:$R$7,0)),"ikke funnet")} -> 0 | F27: {=_xlfn.XLOOKUP($B$6&$B27,'FNR tidsserier'!$B$7:$B$182&'FNR tidsserier'!$C$7:$C$182,INDEX('FNR tidsserier'!$D$7:$R$182,,MATCH(F$5,'FNR tidsserier'!$D$7:$R$7,0)),"ikke funnet")} -> 0 | G27: {=_xlfn.XLOOKUP($B$6&$B27,'FNR tidsserier'!$B$7:$B$182&'FNR tidsserier'!$C$7:$C$182,INDEX('FNR tidsserier'!$D$7:$R$182,,MATCH(G$5,'FNR tidsserier'!$D$7:$R$7,0)),"ikke funnet")} -> 0 | H27: =IFERROR(G27*_xlfn.XLOOKUP($B27,$B$96:$B$117,$C$96:$C$117),0) -> 0 | I27: =IFERROR(H27*_xlfn.XLOOKUP($B27,$B$96:$B$117,$D$96:$D$117),0) -> 0
B28: Utvinning av råolje og naturgass, inkl. tjenester | C28: {=_xlfn.XLOOKUP($B$6&$B28,'FNR tidsserier'!$B$7:$B$182&'FNR tidsserier'!$C$7:$C$182,INDEX('FNR tidsserier'!$D$7:$R$182,,MATCH(C$5,'FNR tidsserier'!$D$7:$R$7,0)),"ikke funnet")} -> 0 | D28: {=_xlfn.XLOOKUP($B$6&$B28,'FNR tidsserier'!$B$7:$B$182&'FNR tidsserier'!$C$7:$C$182,INDEX('FNR tidsserier'!$D$7:$R$182,,MATCH(D$5,'FNR tidsserier'!$D$7:$R$7,0)),"ikke funnet")} -> 0 | E28: {=_xlfn.XLOOKUP($B$6&$B28,'FNR tidsserier'!$B$7:$B$182&'FNR tidsserier'!$C$7:$C$182,INDEX('FNR tidsserier'!$D$7:$R$182,,MATCH(E$5,'FNR tidsserier'!$D$7:$R$7,0)),"ikke funnet")} -> - | F28: {=_xlfn.XLOOKUP($B$6&$B28,'FNR tidsserier'!$B$7:$B$182&'FNR tidsserier'!$C$7:$C$182,INDEX('FNR tidsserier'!$D$7:$R$182,,MATCH(F$5,'FNR tidsserier'!$D$7:$R$7,0)),"ikke funnet")} -> - | G28: {=_xlfn.XLOOKUP($B$6&$B28,'FNR tidsserier'!$B$7:$B$182&'FNR tidsserier'!$C$7:$C$182,INDEX('FNR tidsserier'!$D$7:$R$182,,MATCH(G$5,'FNR tidsserier'!$D$7:$R$7,0)),"ikke funnet")} -> - | H28: =IFERROR(G28*_xlfn.XLOOKUP($B28,$B$96:$B$117,$C$96:$C$117),0) -> 0 | I28: =IFERROR(H28*_xlfn.XLOOKUP($B28,$B$96:$B$117,$D$96:$D$117),0) -> 0
B29: Fiske, fangst og akvakultur | C29: {=_xlfn.XLOOKUP($B$6&$B29,'FNR tidsserier'!$B$7:$B$182&'FNR tidsserier'!$C$7:$C$182,INDEX('FNR tidsserier'!$D$7:$R$182,,MATCH(C$5,'FNR tidsserier'!$D$7:$R$7,0)),"ikke funnet")} -> 0 | D29: {=_xlfn.XLOOKUP($B$6&$B29,'FNR tidsserier'!$B$7:$B$182&'FNR tidsserier'!$C$7:$C$182,INDEX('FNR tidsserier'!$D$7:$R$182,,MATCH(D$5,'FNR tidsserier'!$D$7:$R$7,0)),"ikke funnet")} -> 0 | E29: {=_xlfn.XLOOKUP($B$6&$B29,'FNR tidsserier'!$B$7:$B$182&'FNR tidsserier'!$C$7:$C$182,INDEX('FNR tidsserier'!$D$7:$R$182,,MATCH(E$5,'FNR tidsserier'!$D$7:$R$7,0)),"ikke funnet")} -> - | F29: {=_xlfn.XLOOKUP($B$6&$B29,'FNR tidsserier'!$B$7:$B$182&'FNR tidsserier'!$C$7:$C$182,INDEX('FNR tidsserier'!$D$7:$R$182,,MATCH(F$5,'FNR tidsserier'!$D$7:$R$7,0)),"ikke funnet")} -> - | G29: {=_xlfn.XLOOKUP($B$6&$B29,'FNR tidsserier'!$B$7:$B$182&'FNR tidsserier'!$C$7:$C$182,INDEX('FNR tidsserier'!$D$7:$R$182,,MATCH(G$5,'FNR tidsserier'!$D$7:$R$7,0)),"ikke funnet")} -> - | H29: =IFERROR(G29*_xlfn.XLOOKUP($B29,$B$96:$B$117,$C$96:$C$117),0) -> 0 | I29: =IFERROR(H29*_xlfn.XLOOKUP($B29,$B$96:$B$117,$D$96:$D$117),0) -> 0
B30: Fastlands-Norge | C30: {=_xlfn.XLOOKUP($B$6&$B30,'FNR tidsserier'!$B$7:$B$182&'FNR tidsserier'!$C$7:$C$182,INDEX('FNR tidsserier'!$D$7:$R$182,,MATCH(C$5,'FNR tidsserier'!$D$7:$R$7,0)),"ikke funnet")} -> 0 | D30: {=_xlfn.XLOOKUP($B$6&$B30,'FNR tidsserier'!$B$7:$B$182&'FNR tidsserier'!$C$7:$C$182,INDEX('FNR tidsserier'!$D$7:$R$182,,MATCH(D$5,'FNR tidsserier'!$D$7:$R$7,0)),"ikke funnet")} -> 0 | E30: {=_xlfn.XLOOKUP($B$6&$B30,'FNR tidsserier'!$B$7:$B$182&'FNR tidsserier'!$C$7:$C$182,INDEX('FNR tidsserier'!$D$7:$R$182,,MATCH(E$5,'FNR tidsserier'!$D$7:$R$7,0)),"ikke funnet")} -> - | F30: {=_xlfn.XLOOKUP($B$6&$B30,'FNR tidsserier'!$B$7:$B$182&'FNR tidsserier'!$C$7:$C$182,INDEX('FNR tidsserier'!$D$7:$R$182,,MATCH(F$5,'FNR tidsserier'!$D$7:$R$7,0)),"ikke funnet")} -> - | G30: {=_xlfn.XLOOKUP($B$6&$B30,'FNR tidsserier'!$B$7:$B$182&'FNR tidsserier'!$C$7:$C$182,INDEX('FNR tidsserier'!$D$7:$R$182,,MATCH(G$5,'FNR tidsserier'!$D$7:$R$7,0)),"ikke funnet")} -> - | H30: =IFERROR(G30*_xlfn.XLOOKUP($B30,$B$96:$B$117,$C$96:$C$117),0) -> 0 | I30: =IFERROR(H30*_xlfn.XLOOKUP($B30,$B$96:$B$117,$D$96:$D$117),0) -> 0
B31: Transport utenom utenriks sjøfart | C31: {=_xlfn.XLOOKUP($B$6&$B31,'FNR tidsserier'!$B$7:$B$182&'FNR tidsserier'!$C$7:$C$182,INDEX('FNR tidsserier'!$D$7:$R$182,,MATCH(C$5,'FNR tidsserier'!$D$7:$R$7,0)),"ikke funnet")} -> 0 | D31: {=_xlfn.XLOOKUP($B$6&$B31,'FNR tidsserier'!$B$7:$B$182&'FNR tidsserier'!$C$7:$C$182,INDEX('FNR tidsserier'!$D$7:$R$182,,MATCH(D$5,'FNR tidsserier'!$D$7:$R$7,0)),"ikke funnet")} -> 0 | E31: {=_xlfn.XLOOKUP($B$6&$B31,'FNR tidsserier'!$B$7:$B$182&'FNR tidsserier'!$C$7:$C$182,INDEX('FNR tidsserier'!$D$7:$R$182,,MATCH(E$5,'FNR tidsserier'!$D$7:$R$7,0)),"ikke funnet")} -> 0 | F31: {=_xlfn.XLOOKUP($B$6&$B31,'FNR tidsserier'!$B$7:$B$182&'FNR tidsserier'!$C$7:$C$182,INDEX('FNR tidsserier'!$D$7:$R$182,,MATCH(F$5,'FNR tidsserier'!$D$7:$R$7,0)),"ikke funnet")} -> 0 | G31: {=_xlfn.XLOOKUP($B$6&$B31,'FNR tidsserier'!$B$7:$B$182&'FNR tidsserier'!$C$7:$C$182,INDEX('FNR tidsserier'!$D$7:$R$182,,MATCH(G$5,'FNR tidsserier'!$D$7:$R$7,0)),"ikke funnet")} -> 0 | H31: =IFERROR(G31*_xlfn.XLOOKUP($B31,$B$96:$B$117,$C$96:$C$117),0) -> 0 | I31: =IFERROR(H31*_xlfn.XLOOKUP($B31,$B$96:$B$117,$D$96:$D$117),0) -> 0
B33: Totalt for næringer | C33: =C85 -> 70772 | D33: =D85 -> 72842 | E33: =SUM(E7:E31) -> 71586.022 | F33: =SUM(F7:F31) -> 80769.663 | G33: =SUM(G7:G31) -> 89798.138 | H33: =SUM(H7:H31) -> 86489.868 | I33: =SUM(I7:I31) -> 87593.616
B37: Understøttende beregninger:
C40: 2018 | D40: 2019 | E40: 2020 | F40: 2021 | G40: 2022 | H40: 2023 | I40: 2024
B41: Elektrisitets-, gass- og varmtvannsforsyning | C41: 7098 | D41: 6298 | E41: =D41*E47 -> 6540.5821 | F41: =E41*F47 -> 12467.809 | G41: =F41*G47 -> 18935.982 | H41: =G41*C99 -> 13393.806 | I41: =H41*D99 -> 13784.698
B42: Informasjon og kommunikasjon | C42: 1453 | D42: 1489 | E42: =D42*E48 -> 1370.4766 | F42: =E42*F48 -> 1670.6181 | G42: =F42*G48 -> 1636.2693 | H42: =G42*C106 -> 1818.957 | I42: =H42*D106 -> 1942.1638
B43: Bergverksdrift | C43: 186 | D43: 155 | E43: =D43*E49 -> 180.29311 | F43: =E43*F49 -> 189.29748 | G43: =F43*G49 -> 209.57964 | H43: =G43*C96 -> 423.22998 | I43: =H43*D96 -> 488.09282
B44: Sum av disse 3 | C44: =SUM(C41:C43) -> 8737 | D44: =SUM(D41:D43) -> 7942 | E44: =SUM(E41:E43) -> 8091.3518 | F44: =SUM(F41:F43) -> 14327.725 | G44: =SUM(G41:G43) -> 20781.831 | H44: =SUM(H41:H43) -> 15635.993 | I44: =SUM(I41:I43) -> 16214.955
D46: Estimert vekst i bruttoprodukt (BRREG) | E46: 2020 | F46: 2021 | G46: 2022
D47: Elektrisitets-, gass- og varmtvannsforsyning | E47: 1.0385173 | F47: 1.9062232 | G47: 1.5187898
D48: Informasjon og kommunikasjon | E48: 0.9204007 | F48: 1.2190051 | G48: 0.97943948
D49: Bergverksdrift | E49: 1.1631814 | F49: 1.049943 | G49: 1.1071444
D52: Samlet bruttoprodukt (FNR alle næringer): | E52: =E85 -> 71586.022 | F52: =F85 -> 80769.663 | G52: =G85 -> 89798.138
...

Sheet FNR tidsserier
C2: Databehandling - Fylkesbasert Nasjonalregnskap
C3: Beregning av estimater før- og etter fylkessammenslåing, og produktivitet | AH3: MNOK
AH4: 1000000
C5: Gule celler - estimerte verdier før og etter fylkessammenslåing
C6: Bruttoprodukt | S6: Sysselsatte | AH6: Produktivitet
D7: 2008 | E7: 2009 | F7: 2010 | G7: 2011 | H7: 2012 | I7: 2013 | J7: 2014 | K7: 2015 | L7: 2016 | M7: 2017 | N7: 2018 | O7: 2019 | P7: 2020 | Q7: 2021 | R7: 2022 | S7: 2008 | T7: 2009 | U7: 2010 | V7: 2011 | W7: 2012 | X7: 2013 | Y7: 2014 | Z7: 2015 | AA7: 2016 | AB7: 2017 | AC7: 2018 | AD7: 2019 | AE7: 2020 | AF7: 2021 | AG7: 2022 | AH7: 2008 | AI7: 2009 | AJ7: 2010 | AK7: 2011 | AL7: 2012 | AM7: 2013 | AN7: 2014 | AO7: 2015 | AP7: 2016 | AQ7: 2017 | AR7: 2018 | AS7: 2019 | AT7: 2020 | AU7: 2021 | AV7: 2022
B8: =C8 -> 08 Telemark (-2019) | C8: 08 Telemark (-2019)
B9: =C8 -> 08 Telemark (-2019) | C9: Utvinning av råolje og naturgass, inkl. tjenester | D9: =_xlfn.XLOOKUP($C9,$C$269:$C$295,D$269:D$295,"-") -> 60 | E9: =_xlfn.XLOOKUP($C9,$C$269:$C$295,E$269:E$295,"-") -> 41 | F9: =_xlfn.XLOOKUP($C9,$C$269:$C$295,F$269:F$295,"-") -> 65 | G9: =_xlfn.XLOOKUP($C9,$C$269:$C$295,G$269:G$295,"-") -> 101 | H9: =_xlfn.XLOOKUP($C9,$C$269:$C$295,H$269:H$295,"-") -> 272 | I9: =_xlfn.XLOOKUP($C9,$C$269:$C$295,I$269:I$295,"-") -> 95 | J9: =_xlfn.XLOOKUP($C9,$C$269:$C$295,J$269:J$295,"-") -> 103 | K9: =_xlfn.XLOOKUP($C9,$C$269:$C$295,K$269:K$295,"-") -> 66 | ... O9: =_xlfn.XLOOKUP($C9,$C$269:$C$295,O$269:O$295,"-") -> 0 | P9: =IFERROR(O9*(P65/O65),"-") -> - | Q9: =IFERROR(P9*(Q65/P65),"-") -> - | R9: =IFERROR(Q9*(R65/Q65),"-") -> - | S9: =_xlfn.XLOOKUP($C9,$C$269:$C$295,S$269:S$295,"-") -> 84 | T9: =_xlfn.XLOOKUP($C9,$C$269:$C$295,T$269:T$295,"-") -> 62 | U9: =_xlfn.XLOOKUP($C9,$C$269:$C$295,U$269:U$295,"-") -> 88 | V9: =_xlfn.XLOOKUP($C9,$C$269:$C$295,V$269:V$295,"-") -> 73 | W9: =_xlfn.XLOOKUP($C9,$C$269:$C$295,W$269:W$295,"-") -> 80 | X9: =_xlfn.XLOOKUP($C9,$C$269:$C$295,X$269:X$295,"-") -> 67 | Y9: =_xlfn.XLOOKUP($C9,$C$269:$C$295,Y$269:Y$295,"-") -> 67 | Z9: =_xlfn.XLOOKUP($C9,$C$269:$C$295,Z$269:Z$295,"-") -> 65 | ... AD9: =_xlfn.XLOOKUP($C9,$C$269:$C$295,AD$269:AD$295,"-") -> 0 | AE9: =IFERROR(AD9*(AE65/AD65),"-") -> - | AF9: =IFERROR(AE9*(AF65/AE65),"-") -> - | AG9: =IFERROR(AF9*(AG65/AF65),"-") -> - | AH9: =IFERROR(D9*$AH$4/S9,"-") -> 714285.71 | AI9: =IFERROR(E9*$AH$4/T9,"-") -> 661290.32 | AJ9: =IFERROR(F9*$AH$4/U9,"-") -> 738636.36 | AK9: =IFERROR(G9*$AH$4/V9,"-") -> 1383561.6 | AL9: =IFERROR(H9*$AH$4/W9,"-") -> 3400000 | AM9: =IFERROR(I9*$AH$4/X9,"-") -> 1417910.4 | AN9: =IFERROR(J9*$AH$4/Y9,"-") -> 1537313.4 | AO9: =IFERROR(K9*$AH$4/Z9,"-") -> 1015384.6 | ... AV9: =IFERROR(R9*$AH$4/AG9,"-") -> -
B10: =C8 -> 08 Telemark (-2019) | C10: Helse- og omsorgstjenester | D10: =_xlfn.XLOOKUP($C10,$C$269:$C$295,D$269:D$295,"-") -> 7185 | E10: =_xlfn.XLOOKUP($C10,$C$269:$C$295,E$269:E$295,"-") -> 7558 | F10: =_xlfn.XLOOKUP($C10,$C$269:$C$295,F$269:F$295,"-") -> 7888 | G10: =_xlfn.XLOOKUP($C10,$C$269:$C$295,G$269:G$295,"-") -> 8512 | H10: =_xlfn.XLOOKUP($C10,$C$269:$C$295,H$269:H$295,"-") -> 9165 | I10: =_xlfn.XLOOKUP($C10,$C$269:$C$295,I$269:I$295,"-") -> 9493 | J10: =_xlfn.XLOOKUP($C10,$C$269:$C$295,J$269:J$295,"-") -> 10009 | K10: =_xlfn.XLOOKUP($C10,$C$269:$C$295,K$269:K$295,"-") -> 10586 | ... O10: =_xlfn.XLOOKUP($C10,$C$269:$C$295,O$269:O$295,"-") -> 12046 | P10: =IFERROR(O10*(P66/O66),"-") -> 12005.999 | Q10: =IFERROR(P10*(Q66/P66),"-") -> 12733.049 | R10: =IFERROR(Q10*(R66/Q66),"-") -> 13726.479 | S10: =_xlfn.XLOOKUP($C10,$C$269:$C$295,S$269:S$295,"-") -> 6538 | T10: =_xlfn.XLOOKUP($C10,$C$269:$C$295,T$269:T$295,"-") -> 6938 | U10: =_xlfn.XLOOKUP($C10,$C$269:$C$295,U$269:U$295,"-") -> 7063 | V10: =_xlfn.XLOOKUP($C10,$C$269:$C$295,V$269:V$295,"-") -> 7613 | W10: =_xlfn.XLOOKUP($C10,$C$269:$C$295,W$269:W$295,"-") -> 8188 | X10: =_xlfn.XLOOKUP($C10,$C$269:$C$295,X$269:X$295,"-") -> 8492 | Y10: =_xlfn.XLOOKUP($C10,$C$269:$C$295,Y$269:Y$295,"-") -> 8914 | Z10: =_xlfn.XLOOKUP($C10,$C$269:$C$295,Z$269:Z$295,"-") -> 9473 | ... AD10: =_xlfn.XLOOKUP($C10,$C$269:$C$295,AD$269:AD$295,"-") -> 10872 | AE10: =IFERROR(AD10*(AE66/AD66),"-") -> 10854.422 | AF10: =IFERROR(AE10*(AF66/AE66),"-") -> 11413.842 | AG10: =IFERROR(AF10*(AG66/AF66),"-") -> 12344.598 | AH10: =IFERROR(D10*$AH$4/S10,"-") -> 1098959.9 | AI10: =IFERROR(E10*$AH$4/T10,"-") -> 1089362.9 | AJ10: =IFERROR(F10*$AH$4/U10,"-") -> 1116805.9 | AK10: =IFERROR(G10*$AH$4/V10,"-") -> 1118087.5 | AL10: =IFERROR(H10*$AH$4/W10,"-") -> 1119321 | AM10: =IFERROR(I10*$AH$4/X10,"-") -> 1117875.6 | AN10: =IFERROR(J10*$AH$4/Y10,"-") -> 1122840.5 | AO10: =IFERROR(K10*$AH$4/Z10,"-") -> 1117491.8 | ... AV10: =IFERROR(R10*$AH$4/AG10,"-") -> 1111942.2
B11: =C8 -> 08 Telemark (-2019) | C11: Varehandel og reparasjon av motorvogner | D11: =_xlfn.XLOOKUP($C11,$C$269:$C$295,D$269:D$295,"-") -> 4518 | E11: =_xlfn.XLOOKUP($C11,$C$269:$C$295,E$269:E$295,"-") -> 4264 | F11: =_xlfn.XLOOKUP($C11,$C$269:$C$295,F$269:F$295,"-") -> 4360 | G11: =_xlfn.XLOOKUP($C11,$C$269:$C$295,G$269:G$295,"-") -> 4428 | H11: =_xlfn.XLOOKUP($C11,$C$269:$C$295,H$269:H$295,"-") -> 4687 | I11: =_xlfn.XLOOKUP($C11,$C$269:$C$295,I$269:I$295,"-") -> 4575 | J11: =_xlfn.XLOOKUP($C11,$C$269:$C$295,J$269:J$295,"-") -> 4814 | K11: =_xlfn.XLOOKUP($C11,$C$269:$C$295,K$269:K$295,"-") -> 5530 | ... O11: =_xlfn.XLOOKUP($C11,$C$269:$C$295,O$269:O$295,"-") -> 6543 | P11: =IFERROR(O11*(P67/O67),"-") -> 7271.9079 | Q11: =IFERROR(P11*(Q67/P67),"-") -> 8057.2361 | R11: =IFERROR(Q11*(R67/Q67),"-") -> 7846.2734 | S11: =_xlfn.XLOOKUP($C11,$C$269:$C$295,S$269:S$295,"-") -> 3386 | T11: =_xlfn.XLOOKUP($C11,$C$269:$C$295,T$269:T$295,"-") -> 3339 | U11: =_xlfn.XLOOKUP($C11,$C$269:$C$295,U$269:U$295,"-") -> 3414 | V11: =_xlfn.XLOOKUP($C11,$C$269:$C$295,V$269:V$295,"-") -> 3532 | W11: =_xlfn.XLOOKUP($C11,$C$269:$C$295,W$269:W$295,"-") -> 3719 | X11: =_xlfn.XLOOKUP($C11,$C$269:$C$295,X$269:X$295,"-") -> 3925 | Y11: =_xlfn.XLOOKUP($C11,$C$269:$C$295,Y$269:Y$295,"-") -> 3912 | Z11: =_xlfn.XLOOKUP($C11,$C$269:$C$295,Z$269:Z$295,"-") -> 4083 | ... AD11: =_xlfn.XLOOKUP($C11,$C$269:$C$295,AD$269:AD$295,"-") -> 4571 | AE11: =IFERROR(AD11*(AE67/AD67),"-") -> 4604.4911 | AF11: =IFERROR(AE11*(AF67/AE67),"-") -> 5094.254 | AG11: =IFERROR(AF11*(AG67/AF67),"-") -> 5339.1354 | AH11: =IFERROR(D11*$AH$4/S11,"-") -> 1334317.8 | AI11: =IFERROR(E11*$AH$4/T11,"-") -> 1277029.1 | AJ11: =IFERROR(F11*$AH$4/U11,"-") -> 1277094.3 | AK11: =IFERROR(G11*$AH$4/V11,"-") -> 1253680.6 | AL11: =IFERROR(H11*$AH$4/W11,"-") -> 1260285 | AM11: =IFERROR(I11*$AH$4/X11,"-") -> 1165605.1 | AN11: =IFERROR(J11*$AH$4/Y11,"-") -> 1230572.6 | AO11: =IFERROR(K11*$AH$4/Z11,"-") -> 1354396.3 | ... AV11: =IFERROR(R11*$AH$4/AG11,"-") -> 1469577.5
B12: =C8 -> 08 Telemark (-2019) | C12: Industri | D12: =_xlfn.XLOOKUP($C12,$C$269:$C$295,D$269:D$295,"-") -> 9617 | E12: =_xlfn.XLOOKUP($C12,$C$269:$C$295,E$269:E$295,"-") -> 8464 | F12: =_xlfn.XLOOKUP($C12,$C$269:$C$295,F$269:F$295,"-") -> 8786 | G12: =_xlfn.XLOOKUP($C12,$C$269:$C$295,G$269:G$295,"-") -> 8033 | H12: =_xlfn.XLOOKUP($C12,$C$269:$C$295,H$269:H$295,"-") -> 7245 | I12: =_xlfn.XLOOKUP($C12,$C$269:$C$295,I$269:I$295,"-") -> 8608 | J12: =_xlfn.XLOOKUP($C12,$C$269:$C$295,J$269:J$295,"-") -> 8230 | K12: =_xlfn.XLOOKUP($C12,$C$269:$C$295,K$269:K$295,"-") -> 9927 | ... O12: =_xlfn.XLOOKUP($C12,$C$269:$C$295,O$269:O$295,"-") -> 10055 | P12: =IFERROR(O12*(P68/O68),"-") -> 9918.2753 | Q12: =IFERROR(P12*(Q68/P68),"-") -> 10857.706 | R12: =IFERROR(Q12*(R68/Q68),"-") -> 11377.26 | S12: =_xlfn.XLOOKUP($C12,$C$269:$C$295,S$269:S$295,"-") -> 5009 | T12: =_xlfn.XLOOKUP($C12,$C$269:$C$295,T$269:T$295,"-") -> 4870 | U12: =_xlfn.XLOOKUP($C12,$C$269:$C$295,U$269:U$295,"-") -> 4845 | V12: =_xlfn.XLOOKUP($C12,$C$269:$C$295,V$269:V$295,"-") -> 4938 | W12: =_xlfn.XLOOKUP($C12,$C$269:$C$295,W$269:W$295,"-") -> 4917 | X12: =_xlfn.XLOOKUP($C12,$C$269:$C$295,X$269:X$295,"-") -> 5029 | Y12: =_xlfn.XLOOKUP($C12,$C$269:$C$295,Y$269:Y$295,"-") -> 5184 | Z12: =_xlfn.XLOOKUP($C12,$C$269:$C$295,Z$269:Z$295,"-") -> 5138 | ... AD12: =_xlfn.XLOOKUP($C12,$C$269:$C$295,AD$269:AD$295,"-") -> 6599 | AE12: =IFERROR(AD12*(AE68/AD68),"-") -> 6105.5207 | AF12: =IFERROR(AE12*(AF68/AE68),"-") -> 6559.5902 | AG12: =IFERROR(AF12*(AG68/AF68),"-") -> 6983.6739 | AH12: =IFERROR(D12*$AH$4/S12,"-") -> 1919944.1 | AI12: =IFERROR(E12*$AH$4/T12,"-") -> 1737987.7 | AJ12: =IFERROR(F12*$AH$4/U12,"-") -> 1813415.9 | AK12: =IFERROR(G12*$AH$4/V12,"-") -> 1626772 | AL12: =IFERROR(H12*$AH$4/W12,"-") -> 1473459.4 | AM12: =IFERROR(I12*$AH$4/X12,"-") -> 1711672.3 | AN12: =IFERROR(J12*$AH$4/Y12,"-") -> 1587577.2 | AO12: =IFERROR(K12*$AH$4/Z12,"-") -> 1932074.7 | ... AV12: =IFERROR(R12*$AH$4/AG12,"-") -> 1629122.5
B13: =C8 -> 08 Telemark (-2019) | C13: Offentlig administrasjon og forsvar | D13: =_xlfn.XLOOKUP($C13,$C$269:$C$295,D$269:D$295,"-") -> 2638 | E13: =_xlfn.XLOOKUP($C13,$C$269:$C$295,E$269:E$295,"-") -> 3044 | F13: =_xlfn.XLOOKUP($C13,$C$269:$C$295,F$269:F$295,"-") -> 3344 | G13: =_xlfn.XLOOKUP($C13,$C$269:$C$295,G$269:G$295,"-") -> 3417 | H13: =_xlfn.XLOOKUP($C13,$C$269:$C$295,H$269:H$295,"-") -> 3591 | I13: =_xlfn.XLOOKUP($C13,$C$269:$C$295,I$269:I$295,"-") -> 3989 | J13: =_xlfn.XLOOKUP($C13,$C$269:$C$295,J$269:J$295,"-") -> 4392 | K13: =_xlfn.XLOOKUP($C13,$C$269:$C$295,K$269:K$295,"-") -> 4471 | ... O13: =_xlfn.XLOOKUP($C13,$C$269:$C$295,O$269:O$295,"-") -> 4833 | P13: =IFERROR(O13*(P69/O69),"-") -> 5119.9232 | Q13: =IFERROR(P13*(Q69/P69),"-") -> 5381.3067 | R13: =IFERROR(Q13*(R69/Q69),"-") -> 5603.9814 | S13: =_xlfn.XLOOKUP($C13,$C$269:$C$295,S$269:S$295,"-") -> 1990 | T13: =_xlfn.XLOOKUP($C13,$C$269:$C$295,T$269:T$295,"-") -> 2352 | U13: =_xlfn.XLOOKUP($C13,$C$269:$C$295,U$269:U$295,"-") -> 2447 | V13: =_xlfn.XLOOKUP($C13,$C$269:$C$295,V$269:V$295,"-") -> 2480 | W13: =_xlfn.XLOOKUP($C13,$C$269:$C$295,W$269:W$295,"-") -> 2582 | X13: =_xlfn.XLOOKUP($C13,$C$269:$C$295,X$269:X$295,"-") -> 2880 | Y13: =_xlfn.XLOOKUP($C13,$C$269:$C$295,Y$269:Y$295,"-") -> 3149 | Z13: =_xlfn.XLOOKUP($C13,$C$269:$C$295,Z$269:Z$295,"-") -> 3157 | ... AD13: =_xlfn.XLOOKUP($C13,$C$269:$C$295,AD$269:AD$295,"-") -> 3435 | AE13: =IFERROR(AD13*(AE69/AD69),"-") -> 3621.1767 | AF13: =IFERROR(AE13*(AF69/AE69),"-") -> 3754.563 | AG13: =IFERROR(AF13*(AG69/AF69),"-") -> 3851.2782 | AH13: =IFERROR(D13*$AH$4/S13,"-") -> 1325628.1 | AI13: =IFERROR(E13*$AH$4/T13,"-") -> 1294217.7 | AJ13: =IFERROR(F13*$AH$4/U13,"-") -> 1366571.3 | AK13: =IFERROR(G13*$AH$4/V13,"-") -> 1377822.6 | AL13: =IFERROR(H13*$AH$4/W13,"-") -> 1390782.3 | AM13: =IFERROR(I13*$AH$4/X13,"-") -> 1385069.4 | AN13: =IFERROR(J13*$AH$4/Y13,"-") -> 1394728.5 | AO13: =IFERROR(K13*$AH$4/Z13,"-") -> 1416217.9 | ... AV13: =IFERROR(R13*$AH$4/AG13,"-") -> 1455096.5
B14: =C8 -> 08 Telemark (-2019) | C14: Bygge- og anleggsvirksomhet | D14: =_xlfn.XLOOKUP($C14,$C$269:$C$295,D$269:D$295,"-") -> 4183 | E14: =_xlfn.XLOOKUP($C14,$C$269:$C$295,E$269:E$295,"-") -> 3830 | F14: =_xlfn.XLOOKUP($C14,$C$269:$C$295,F$269:F$295,"-") -> 4161 | G14: =_xlfn.XLOOKUP($C14,$C$269:$C$295,G$269:G$295,"-") -> 4115 | H14: =_xlfn.XLOOKUP($C14,$C$269:$C$295,H$269:H$295,"-") -> 4519 | I14: =_xlfn.XLOOKUP($C14,$C$269:$C$295,I$269:I$295,"-") -> 4373 | J14: =_xlfn.XLOOKUP($C14,$C$269:$C$295,J$269:J$295,"-") -> 4451 | K14: =_xlfn.XLOOKUP($C14,$C$269:$C$295,K$269:K$295,"-") -> 4997 | ... O14: =_xlfn.XLOOKUP($C14,$C$269:$C$295,O$269:O$295,"-") -> 6392 | P14: =IFERROR(O14*(P70/O70),"-") -> 6363.4974 | Q14: =IFERROR(P14*(Q70/P70),"-") -> 6756.6771 | R14: =IFERROR(Q14*(R70/Q70),"-") -> 7291.1983 | S14: =_xlfn.XLOOKUP($C14,$C$269:$C$295,S$269:S$295,"-") -> 2646 | T14: =_xlfn.XLOOKUP($C14,$C$269:$C$295,T$269:T$295,"-") -> 2491 | U14: =_xlfn.XLOOKUP($C14,$C$269:$C$295,U$269:U$295,"-") -> 2669 | V14: =_xlfn.XLOOKUP($C14,$C$269:$C$295,V$269:V$295,"-") -> 2861 | W14: =_xlfn.XLOOKUP($C14,$C$269:$C$295,W$269:W$295,"-") -> 3028 | X14: =_xlfn.XLOOKUP($C14,$C$269:$C$295,X$269:X$295,"-") -> 3062 | Y14: =_xlfn.XLOOKUP($C14,$C$269:$C$295,Y$269:Y$295,"-") -> 3054 | Z14: =_xlfn.XLOOKUP($C14,$C$269:$C$295,Z$269:Z$295,"-") -> 3153 | ... AD14: =_xlfn.XLOOKUP($C14,$C$269:$C$295,AD$269:AD$295,"-") -> 4205 | AE14: =IFERROR(AD14*(AE70/AD70),"-") -> 4232.0774 | AF14: =IFERROR(AE14*(AF70/AE70),"-") -> 4463.5697 | AG14: =IFERROR(AF14*(AG70/AF70),"-") -> 4819.0078 | AH14: =IFERROR(D14*$AH$4/S14,"-") -> 1580876.8 | AI14: =IFERROR(E14*$AH$4/T14,"-") -> 1537535.1 | AJ14: =IFERROR(F14*$AH$4/U14,"-") -> 1559010.9 | AK14: =IFERROR(G14*$AH$4/V14,"-") -> 1438308.3 | AL14: =IFERROR(H14*$AH$4/W14,"-") -> 1492404.2 | AM14: =IFERROR(I14*$AH$4/X14,"-") -> 1428151.5 | AN14: =IFERROR(J14*$AH$4/Y14,"-") -> 1457432.9 | AO14: =IFERROR(K14*$AH$4/Z14,"-") -> 1584839.8 | ... AV14: =IFERROR(R14*$AH$4/AG14,"-") -> 1513008.2
B15: =C8 -> 08 Telemark (-2019) | C15: Undervisning | D15: =_xlfn.XLOOKUP($C15,$C$269:$C$295,D$269:D$295,"-") -> 3031 | E15: =_xlfn.XLOOKUP($C15,$C$269:$C$295,E$269:E$295,"-") -> 3201 | F15: =_xlfn.XLOOKUP($C15,$C$269:$C$295,F$269:F$295,"-") -> 3307 | G15: =_xlfn.XLOOKUP($C15,$C$269:$C$295,G$269:G$295,"-") -> 3526 | H15: =_xlfn.XLOOKUP($C15,$C$269:$C$295,H$269:H$295,"-") -> 3779 | I15: =_xlfn.XLOOKUP($C15,$C$269:$C$295,I$269:I$295,"-") -> 3980 | J15: =_xlfn.XLOOKUP($C15,$C$269:$C$295,J$269:J$295,"-") -> 4043 | K15: =_xlfn.XLOOKUP($C15,$C$269:$C$295,K$269:K$295,"-") -> 4251 | ... O15: =_xlfn.XLOOKUP($C15,$C$269:$C$295,O$269:O$295,"-") -> 5175 | P15: =IFERROR(O15*(P71/O71),"-") -> 5044.3672 | Q15: =IFERROR(P15*(Q71/P71),"-") -> 5343.1456 | R15: =IFERROR(Q15*(R71/Q71),"-") -> 5882.8885 | S15: =_xlfn.XLOOKUP($C15,$C$269:$C$295,S$269:S$295,"-") -> 2615 | T15: =_xlfn.XLOOKUP($C15,$C$269:$C$295,T$269:T$295,"-") -> 2771 | U15: =_xlfn.XLOOKUP($C15,$C$269:$C$295,U$269:U$295,"-") -> 2825 | V15: =_xlfn.XLOOKUP($C15,$C$269:$C$295,V$269:V$295,"-") -> 2994 | W15: =_xlfn.XLOOKUP($C15,$C$269:$C$295,W$269:W$295,"-") -> 3134 | X15: =_xlfn.XLOOKUP($C15,$C$269:$C$295,X$269:X$295,"-") -> 3277 | Y15: =_xlfn.XLOOKUP($C15,$C$269:$C$295,Y$269:Y$295,"-") -> 3352 | Z15: =_xlfn.XLOOKUP($C15,$C$269:$C$295,Z$269:Z$295,"-") -> 3541 | ... AD15: =_xlfn.XLOOKUP($C15,$C$269:$C$295,AD$269:AD$295,"-") -> 4181 | AE15: =IFERROR(AD15*(AE71/AD71),"-") -> 4080.435 | AF15: =IFERROR(AE15*(AF71/AE71),"-") -> 4280.7018 | AG15: =IFERROR(AF15*(AG71/AF71),"-") -> 4657.9284 | AH15: =IFERROR(D15*$AH$4/S15,"-") -> 1159082.2 | AI15: =IFERROR(E15*$AH$4/T15,"-") -> 1155178.6 | AJ15: =IFERROR(F15*$AH$4/U15,"-") -> 1170619.5 | AK15: =IFERROR(G15*$AH$4/V15,"-") -> 1177688.7 | AL15: =IFERROR(H15*$AH$4/W15,"-") -> 1205807.3 | AM15: =IFERROR(I15*$AH$4/X15,"-") -> 1214525.5 | AN15: =IFERROR(J15*$AH$4/Y15,"-") -> 1206145.6 | AO15: =IFERROR(K15*$AH$4/Z15,"-") -> 1200508.3 | ... AV15: =IFERROR(R15*$AH$4/AG15,"-") -> 1262983.9
B16: =C8 -> 08 Telemark (-2019) | C16: Faglig, vitenskapelig og teknisk tjenesteyting | D16: =_xlfn.XLOOKUP($C16,$C$269:$C$295,D$269:D$295,"-") -> 1916 | E16: =_xlfn.XLOOKUP($C16,$C$269:$C$295,E$269:E$295,"-") -> 1911 | F16: =_xlfn.XLOOKUP($C16,$C$269:$C$295,F$269:F$295,"-") -> 1774 | G16: =_xlfn.XLOOKUP($C16,$C$269:$C$295,G$269:G$295,"-") -> 1888 | H16: =_xlfn.XLOOKUP($C16,$C$269:$C$295,H$269:H$295,"-") -> 2187 | I16: =_xlfn.XLOOKUP($C16,$C$269:$C$295,I$269:I$295,"-") -> 2117 | J16: =_xlfn.XLOOKUP($C16,$C$269:$C$295,J$269:J$295,"-") -> 2251 | K16: =_xlfn.XLOOKUP($C16,$C$269:$C$295,K$269:K$295,"-") -> 2375 | ... O16: =_xlfn.XLOOKUP($C16,$C$269:$C$295,O$269:O$295,"-") -> 3581 | P16: =IFERROR(O16*(P72/O72),"-") -> 3466.7742 | Q16: =IFERROR(P16*(Q72/P72),"-") -> 4333.4678 | R16: =IFERROR(Q16*(R72/Q72),"-") -> 5056.6013 | S16: =_xlfn.XLOOKUP($C16,$C$269:$C$295,S$269:S$295,"-") -> 1296 | T16: =_xlfn.XLOOKUP($C16,$C$269:$C$295,T$269:T$295,"-") -> 1302 | U16: =_xlfn.XLOOKUP($C16,$C$269:$C$295,U$269:U$295,"-") -> 1332 | V16: =_xlfn.XLOOKUP($C16,$C$269:$C$295,V$269:V$295,"-") -> 1435 | W16: =_xlfn.XLOOKUP($C16,$C$269:$C$295,W$269:W$295,"-") -> 1554 | X16: =_xlfn.XLOOKUP($C16,$C$269:$C$295,X$269:X$295,"-") -> 1458 | Y16: =_xlfn.XLOOKUP($C16,$C$269:$C$295,Y$269:Y$295,"-") -> 1638 | Z16: =_xlfn.XLOOKUP($C16,$C$269:$C$295,Z$269:Z$295,"-") -> 1607 | ... AD16: =_xlfn.XLOOKUP($C16,$C$269:$C$295,AD$269:AD$295,"-") -> 1945 | AE16: =IFERROR(AD16*(AE72/AD72),"-") -> 1940.5107 | AF16: =IFERROR(AE16*(AF72/AE72),"-") -> 2085.2914 | AG16: =IFERROR(AF16*(AG72/AF72),"-") -> 2303.3978 | AH16: =IFERROR(D16*$AH$4/S16,"-") -> 1478395.1 | AI16: =IFERROR(E16*$AH$4/T16,"-") -> 1467741.9 | AJ16: =IFERROR(F16*$AH$4/U16,"-") -> 1331831.8 | AK16: =IFERROR(G16*$AH$4/V16,"-") -> 1315679.4 | AL16: =IFERROR(H16*$AH$4/W16,"-") -> 1407335.9 | AM16: =IFERROR(I16*$AH$4/X16,"-") -> 1451989 | AN16: =IFERROR(J16*$AH$4/Y16,"-") -> 1374236.9 | AO16: =IFERROR(K16*$AH$4/Z16,"-") -> 1477909.1 | ... AV16: =IFERROR(R16*$AH$4/AG16,"-") -> 2195279.3
